2025-01-20 21:30:14,406 INFO: Microblog startup [in /Users/stephentrento/flask_app/app/__init__.py:48]
2025-01-20 21:30:30,527 INFO: Microblog startup [in /Users/stephentrento/flask_app/app/__init__.py:48]
2025-01-20 21:33:04,939 INFO: Microblog startup [in /Users/stephentrento/flask_app/app/__init__.py:48]
2025-01-20 21:37:50,290 INFO: Microblog startup [in /Users/stephentrento/flask_app/app/__init__.py:48]
2025-01-22 09:44:20,183 INFO: Microblog startup [in /Users/stephentrento/flask_app/app/__init__.py:48]
2025-01-22 09:44:23,729 INFO: Microblog startup [in /Users/stephentrento/flask_app/app/__init__.py:48]
2025-01-22 09:50:22,258 INFO: Microblog startup [in /Users/stephentrento/flask_app/app/__init__.py:48]
2025-01-22 09:52:22,205 INFO: Microblog startup [in /Users/stephentrento/flask_app/app/__init__.py:48]
2025-01-22 10:05:44,040 INFO: Microblog startup [in /Users/stephentrento/flask_app/app/__init__.py:48]
2025-01-22 10:06:12,853 ERROR: Exception on /map [POST] [in /Users/stephentrento/flask_app/.venv/lib/python3.13/site-packages/flask/app.py:875]
Traceback (most recent call last):
  File "/Users/stephentrento/flask_app/.venv/lib/python3.13/site-packages/flask/app.py", line 1511, in wsgi_app
    response = self.full_dispatch_request()
  File "/Users/stephentrento/flask_app/.venv/lib/python3.13/site-packages/flask/app.py", line 919, in full_dispatch_request
    rv = self.handle_user_exception(e)
  File "/Users/stephentrento/flask_app/.venv/lib/python3.13/site-packages/flask/app.py", line 917, in full_dispatch_request
    rv = self.dispatch_request()
  File "/Users/stephentrento/flask_app/.venv/lib/python3.13/site-packages/flask/app.py", line 902, in dispatch_request
    return self.ensure_sync(self.view_functions[rule.endpoint])(**view_args)  # type: ignore[no-any-return]
           ~~~~~~~~~~~~~~~~~~~~~~~~~~~~~~~~~~~~~~~~~~~~~~~~~~~~^^^^^^^^^^^^^
  File "/Users/stephentrento/flask_app/app/routes.py", line 59, in map
    return render_template('map.html')
  File "/Users/stephentrento/flask_app/.venv/lib/python3.13/site-packages/flask/templating.py", line 150, in render_template
    return _render(app, template, context)
  File "/Users/stephentrento/flask_app/.venv/lib/python3.13/site-packages/flask/templating.py", line 131, in _render
    rv = template.render(context)
  File "/Users/stephentrento/flask_app/.venv/lib/python3.13/site-packages/jinja2/environment.py", line 1295, in render
    self.environment.handle_exception()
    ~~~~~~~~~~~~~~~~~~~~~~~~~~~~~~~~~^^
  File "/Users/stephentrento/flask_app/.venv/lib/python3.13/site-packages/jinja2/environment.py", line 942, in handle_exception
    raise rewrite_traceback_stack(source=source)
  File "/Users/stephentrento/flask_app/app/templates/map.html", line 1, in top-level template code
    {% extends 'base.html' %}
  File "/Users/stephentrento/flask_app/app/templates/base.html", line 67, in top-level template code
    {% block content %}{% endblock %}
    ^^^^^^^^^^^^^^^^^^^
  File "/Users/stephentrento/flask_app/app/templates/map.html", line 12, in block 'content'
    {{ form.hidden_tag() }}
    ^^^^^^^^^^^^^^^^^
  File "/Users/stephentrento/flask_app/.venv/lib/python3.13/site-packages/jinja2/environment.py", line 490, in getattr
    return getattr(obj, attribute)
jinja2.exceptions.UndefinedError: 'form' is undefined
2025-01-23 12:22:13,224 INFO: Microblog startup [in /Users/stephentrento/flask_app/app/__init__.py:48]
2025-01-23 12:22:20,690 ERROR: Exception on / [GET] [in /Users/stephentrento/flask_app/.venv/lib/python3.13/site-packages/flask/app.py:875]
Traceback (most recent call last):
  File "/Users/stephentrento/flask_app/.venv/lib/python3.13/site-packages/flask/app.py", line 1511, in wsgi_app
    response = self.full_dispatch_request()
  File "/Users/stephentrento/flask_app/.venv/lib/python3.13/site-packages/flask/app.py", line 919, in full_dispatch_request
    rv = self.handle_user_exception(e)
  File "/Users/stephentrento/flask_app/.venv/lib/python3.13/site-packages/flask/app.py", line 917, in full_dispatch_request
    rv = self.dispatch_request()
  File "/Users/stephentrento/flask_app/.venv/lib/python3.13/site-packages/flask/app.py", line 902, in dispatch_request
    return self.ensure_sync(self.view_functions[rule.endpoint])(**view_args)  # type: ignore[no-any-return]
           ~~~~~~~~~~~~~~~~~~~~~~~~~~~~~~~~~~~~~~~~~~~~~~~~~~~~^^^^^^^^^^^^^
  File "/Users/stephentrento/flask_app/.venv/lib/python3.13/site-packages/flask_login/utils.py", line 290, in decorated_view
    return current_app.ensure_sync(func)(*args, **kwargs)
           ~~~~~~~~~~~~~~~~~~~~~~~~~~~~~^^^^^^^^^^^^^^^^^
  File "/Users/stephentrento/flask_app/app/routes.py", line 41, in index
    return render_template('index.html', title='Home', form=form,
                           posts=posts.items, next_url=next_url,
                           prev_url=prev_url) # render index.html, with title home, form = postform, list of paginated posts, and next/prev otions
  File "/Users/stephentrento/flask_app/.venv/lib/python3.13/site-packages/flask/templating.py", line 150, in render_template
    return _render(app, template, context)
  File "/Users/stephentrento/flask_app/.venv/lib/python3.13/site-packages/flask/templating.py", line 131, in _render
    rv = template.render(context)
  File "/Users/stephentrento/flask_app/.venv/lib/python3.13/site-packages/jinja2/environment.py", line 1295, in render
    self.environment.handle_exception()
    ~~~~~~~~~~~~~~~~~~~~~~~~~~~~~~~~~^^
  File "/Users/stephentrento/flask_app/.venv/lib/python3.13/site-packages/jinja2/environment.py", line 942, in handle_exception
    raise rewrite_traceback_stack(source=source)
  File "/Users/stephentrento/flask_app/app/templates/index.html", line 2, in top-level template code
    {% import "bootstrap_wtf.html" as wtf %}
    ^^^^^^^^^^^^^^^^^^^^^^^^^
  File "/Users/stephentrento/flask_app/app/templates/base.html", line 36, in top-level template code
    <a class="nav-link" aria-current="page" href="{{ url_for('explore') }}">Explore</a>
    ^^^^^^^^^^^
  File "/Users/stephentrento/flask_app/.venv/lib/python3.13/site-packages/flask/app.py", line 1121, in url_for
    return self.handle_url_build_error(error, endpoint, values)
           ~~~~~~~~~~~~~~~~~~~~~~~~~~~^^^^^^^^^^^^^^^^^^^^^^^^^
  File "/Users/stephentrento/flask_app/.venv/lib/python3.13/site-packages/flask/app.py", line 1110, in url_for
    rv = url_adapter.build(  # type: ignore[union-attr]
        endpoint,
    ...<3 lines>...
        force_external=_external,
    )
  File "/Users/stephentrento/flask_app/.venv/lib/python3.13/site-packages/werkzeug/routing/map.py", line 924, in build
    raise BuildError(endpoint, values, method, self)
werkzeug.routing.exceptions.BuildError: Could not build url for endpoint 'explore'. Did you mean 'edit_profile' instead?
