2025-02-03 22:36:35,141 ERROR: Exception on /delete_user/1 [DELETE] [in /Users/stephentrento/flask_app/.venv/lib/python3.13/site-packages/flask/app.py:875]
Traceback (most recent call last):
  File "/Users/stephentrento/flask_app/.venv/lib/python3.13/site-packages/flask/app.py", line 1511, in wsgi_app
    response = self.full_dispatch_request()
  File "/Users/stephentrento/flask_app/.venv/lib/python3.13/site-packages/flask/app.py", line 919, in full_dispatch_request
    rv = self.handle_user_exception(e)
  File "/Users/stephentrento/flask_app/.venv/lib/python3.13/site-packages/flask/app.py", line 917, in full_dispatch_request
    rv = self.dispatch_request()
  File "/Users/stephentrento/flask_app/.venv/lib/python3.13/site-packages/flask/app.py", line 902, in dispatch_request
    return self.ensure_sync(self.view_functions[rule.endpoint])(**view_args)  # type: ignore[no-any-return]
           ~~~~~~~~~~~~~~~~~~~~~~~~~~~~~~~~~~~~~~~~~~~~~~~~~~~~^^^^^^^^^^^^^
  File "/Users/stephentrento/flask_app/app/routes.py", line 180, in delete_user
    db.session.commit()
    ~~~~~~~~~~~~~~~~~^^
  File "/Users/stephentrento/flask_app/.venv/lib/python3.13/site-packages/sqlalchemy/orm/scoping.py", line 599, in commit
    return self._proxied.commit()
           ~~~~~~~~~~~~~~~~~~~~^^
  File "/Users/stephentrento/flask_app/.venv/lib/python3.13/site-packages/sqlalchemy/orm/session.py", line 2032, in commit
    trans.commit(_to_root=True)
    ~~~~~~~~~~~~^^^^^^^^^^^^^^^
  File "<string>", line 2, in commit
  File "/Users/stephentrento/flask_app/.venv/lib/python3.13/site-packages/sqlalchemy/orm/state_changes.py", line 139, in _go
    ret_value = fn(self, *arg, **kw)
  File "/Users/stephentrento/flask_app/.venv/lib/python3.13/site-packages/sqlalchemy/orm/session.py", line 1313, in commit
    self._prepare_impl()
    ~~~~~~~~~~~~~~~~~~^^
  File "<string>", line 2, in _prepare_impl
  File "/Users/stephentrento/flask_app/.venv/lib/python3.13/site-packages/sqlalchemy/orm/state_changes.py", line 139, in _go
    ret_value = fn(self, *arg, **kw)
  File "/Users/stephentrento/flask_app/.venv/lib/python3.13/site-packages/sqlalchemy/orm/session.py", line 1288, in _prepare_impl
    self.session.flush()
    ~~~~~~~~~~~~~~~~~~^^
  File "/Users/stephentrento/flask_app/.venv/lib/python3.13/site-packages/sqlalchemy/orm/session.py", line 4353, in flush
    self._flush(objects)
    ~~~~~~~~~~~^^^^^^^^^
  File "/Users/stephentrento/flask_app/.venv/lib/python3.13/site-packages/sqlalchemy/orm/session.py", line 4488, in _flush
    with util.safe_reraise():
         ~~~~~~~~~~~~~~~~~^^
  File "/Users/stephentrento/flask_app/.venv/lib/python3.13/site-packages/sqlalchemy/util/langhelpers.py", line 146, in __exit__
    raise exc_value.with_traceback(exc_tb)
  File "/Users/stephentrento/flask_app/.venv/lib/python3.13/site-packages/sqlalchemy/orm/session.py", line 4449, in _flush
    flush_context.execute()
    ~~~~~~~~~~~~~~~~~~~~~^^
  File "/Users/stephentrento/flask_app/.venv/lib/python3.13/site-packages/sqlalchemy/orm/unitofwork.py", line 442, in execute
    postsort_actions = self._generate_actions()
  File "/Users/stephentrento/flask_app/.venv/lib/python3.13/site-packages/sqlalchemy/orm/unitofwork.py", line 400, in _generate_actions
    if action.execute(self):
       ~~~~~~~~~~~~~~^^^^^^
  File "/Users/stephentrento/flask_app/.venv/lib/python3.13/site-packages/sqlalchemy/orm/unitofwork.py", line 532, in execute
    self.dependency_processor.presort_deletes(uow, delete_states)
    ~~~~~~~~~~~~~~~~~~~~~~~~~~~~~~~~~~~~~~~~~^^^^^^^^^^^^^^^^^^^^
  File "/Users/stephentrento/flask_app/.venv/lib/python3.13/site-packages/sqlalchemy/orm/dependency.py", line 450, in presort_deletes
    history = uowcommit.get_attribute_history(
        state, self.key, self._passive_delete_flag
    )
  File "/Users/stephentrento/flask_app/.venv/lib/python3.13/site-packages/sqlalchemy/orm/unitofwork.py", line 283, in get_attribute_history
    history = impl.get_history(
        state,
    ...<3 lines>...
        | attributes.NO_RAISE,
    )
  File "/Users/stephentrento/flask_app/.venv/lib/python3.13/site-packages/sqlalchemy/orm/writeonly.py", line 380, in get_history
    c = self._get_collection_history(state, passive)
  File "/Users/stephentrento/flask_app/.venv/lib/python3.13/site-packages/sqlalchemy/orm/writeonly.py", line 404, in _get_collection_history
    return self.collection_history_cls(
           ~~~~~~~~~~~~~~~~~~~~~~~~~~~^
        self, state, passive, apply_to=c
        ^^^^^^^^^^^^^^^^^^^^^^^^^^^^^^^^
    )
    ^
  File "/Users/stephentrento/flask_app/.venv/lib/python3.13/site-packages/sqlalchemy/orm/writeonly.py", line 94, in __init__
    raise exc.InvalidRequestError(
    ...<5 lines>...
    )
sqlalchemy.exc.InvalidRequestError: Attribute User.posts can't load the existing state from the database for this operation; full iteration is not permitted.  If this is a delete operation, configure passive_deletes=True on the User.posts relationship in order to resolve this error.
2025-02-03 22:46:44,704 INFO: Microblog startup [in /Users/stephentrento/flask_app/app/__init__.py:51]
2025-02-03 22:48:24,795 INFO: Microblog startup [in /Users/stephentrento/flask_app/app/__init__.py:51]
2025-02-03 22:49:48,289 INFO: Microblog startup [in /Users/stephentrento/flask_app/app/__init__.py:51]
2025-02-03 22:50:54,400 INFO: Microblog startup [in /Users/stephentrento/flask_app/app/__init__.py:51]
2025-02-03 22:52:44,879 INFO: Microblog startup [in /Users/stephentrento/flask_app/app/__init__.py:51]
2025-02-03 22:53:36,704 ERROR: Exception on /add_event [POST] [in /Users/stephentrento/flask_app/.venv/lib/python3.13/site-packages/flask/app.py:875]
Traceback (most recent call last):
  File "/Users/stephentrento/flask_app/.venv/lib/python3.13/site-packages/flask/app.py", line 1511, in wsgi_app
    response = self.full_dispatch_request()
  File "/Users/stephentrento/flask_app/.venv/lib/python3.13/site-packages/flask/app.py", line 919, in full_dispatch_request
    rv = self.handle_user_exception(e)
  File "/Users/stephentrento/flask_app/.venv/lib/python3.13/site-packages/flask/app.py", line 917, in full_dispatch_request
    rv = self.dispatch_request()
  File "/Users/stephentrento/flask_app/.venv/lib/python3.13/site-packages/flask/app.py", line 902, in dispatch_request
    return self.ensure_sync(self.view_functions[rule.endpoint])(**view_args)  # type: ignore[no-any-return]
           ~~~~~~~~~~~~~~~~~~~~~~~~~~~~~~~~~~~~~~~~~~~~~~~~~~~~^^^^^^^^^^^^^
  File "/Users/stephentrento/flask_app/app/routes.py", line 48, in add_event
    if form.validate_on_submit():
       ^^^^
NameError: name 'form' is not defined. Did you mean: 'format'?
2025-02-04 10:21:08,402 INFO: Microblog startup [in /Users/stephentrento/flask_app/app/__init__.py:51]
2025-02-04 10:23:19,557 INFO: Microblog startup [in /Users/stephentrento/flask_app/app/__init__.py:51]
2025-02-04 10:23:48,569 INFO: Microblog startup [in /Users/stephentrento/flask_app/app/__init__.py:51]
2025-02-04 17:34:18,141 INFO: Microblog startup [in /Users/stephentrento/flask_app/app/__init__.py:51]
2025-02-04 19:23:43,798 INFO: Microblog startup [in /Users/stephentrento/flask_app/app/__init__.py:51]
2025-02-04 21:03:07,282 INFO: Microblog startup [in /Users/stephentrento/flask_app/app/__init__.py:51]
2025-02-04 21:03:14,195 ERROR: Exception on /map [POST] [in /Users/stephentrento/flask_app/.venv/lib/python3.13/site-packages/flask/app.py:875]
Traceback (most recent call last):
  File "/Users/stephentrento/flask_app/.venv/lib/python3.13/site-packages/flask/app.py", line 1511, in wsgi_app
    response = self.full_dispatch_request()
  File "/Users/stephentrento/flask_app/.venv/lib/python3.13/site-packages/flask/app.py", line 919, in full_dispatch_request
    rv = self.handle_user_exception(e)
  File "/Users/stephentrento/flask_app/.venv/lib/python3.13/site-packages/flask/app.py", line 917, in full_dispatch_request
    rv = self.dispatch_request()
  File "/Users/stephentrento/flask_app/.venv/lib/python3.13/site-packages/flask/app.py", line 902, in dispatch_request
    return self.ensure_sync(self.view_functions[rule.endpoint])(**view_args)  # type: ignore[no-any-return]
           ~~~~~~~~~~~~~~~~~~~~~~~~~~~~~~~~~~~~~~~~~~~~~~~~~~~~^^^^^^^^^^^^^
  File "/Users/stephentrento/flask_app/app/routes.py", line 52, in map
    latitude, longitude = get_coordinates(postcode) # get coordinates from postcode automatically
                          ~~~~~~~~~~~~~~~^^^^^^^^^^
  File "/Users/stephentrento/flask_app/app/routes.py", line 38, in get_coordinates
    response = requests.get(url)
               ^^^^^^^^
NameError: name 'requests' is not defined. Did you mean: 'request'?
2025-02-04 21:03:58,988 INFO: Microblog startup [in /Users/stephentrento/flask_app/app/__init__.py:51]
2025-02-04 21:04:34,328 ERROR: Exception on /map [POST] [in /Users/stephentrento/flask_app/.venv/lib/python3.13/site-packages/flask/app.py:875]
Traceback (most recent call last):
  File "/Users/stephentrento/flask_app/.venv/lib/python3.13/site-packages/flask/app.py", line 1511, in wsgi_app
    response = self.full_dispatch_request()
  File "/Users/stephentrento/flask_app/.venv/lib/python3.13/site-packages/flask/app.py", line 919, in full_dispatch_request
    rv = self.handle_user_exception(e)
  File "/Users/stephentrento/flask_app/.venv/lib/python3.13/site-packages/flask/app.py", line 917, in full_dispatch_request
    rv = self.dispatch_request()
  File "/Users/stephentrento/flask_app/.venv/lib/python3.13/site-packages/flask/app.py", line 902, in dispatch_request
    return self.ensure_sync(self.view_functions[rule.endpoint])(**view_args)  # type: ignore[no-any-return]
           ~~~~~~~~~~~~~~~~~~~~~~~~~~~~~~~~~~~~~~~~~~~~~~~~~~~~^^^^^^^^^^^^^
  File "/Users/stephentrento/flask_app/app/routes.py", line 52, in map
    latitude, longitude = get_coordinates(postcode) # get coordinates from postcode automatically
                          ~~~~~~~~~~~~~~~^^^^^^^^^^
  File "/Users/stephentrento/flask_app/app/routes.py", line 38, in get_coordinates
    response = request.get(url)
               ^^^^^^^^^^^
AttributeError: 'Request' object has no attribute 'get'
