2025-01-26 14:54:42,364 ERROR: Exception on /login [POST] [in /Users/stephentrento/flask_app/.venv/lib/python3.13/site-packages/flask/app.py:875]
Traceback (most recent call last):
  File "/Users/stephentrento/flask_app/.venv/lib/python3.13/site-packages/sqlalchemy/engine/base.py", line 1964, in _exec_single_context
    self.dialect.do_execute(
    ~~~~~~~~~~~~~~~~~~~~~~~^
        cursor, str_statement, effective_parameters, context
        ^^^^^^^^^^^^^^^^^^^^^^^^^^^^^^^^^^^^^^^^^^^^^^^^^^^^
    )
    ^
  File "/Users/stephentrento/flask_app/.venv/lib/python3.13/site-packages/sqlalchemy/engine/default.py", line 942, in do_execute
    cursor.execute(statement, parameters)
    ~~~~~~~~~~~~~~^^^^^^^^^^^^^^^^^^^^^^^
sqlite3.IntegrityError: UNIQUE constraint failed: user.username

The above exception was the direct cause of the following exception:

Traceback (most recent call last):
  File "/Users/stephentrento/flask_app/.venv/lib/python3.13/site-packages/flask/app.py", line 1511, in wsgi_app
    response = self.full_dispatch_request()
  File "/Users/stephentrento/flask_app/.venv/lib/python3.13/site-packages/flask/app.py", line 919, in full_dispatch_request
    rv = self.handle_user_exception(e)
  File "/Users/stephentrento/flask_app/.venv/lib/python3.13/site-packages/flask/app.py", line 917, in full_dispatch_request
    rv = self.dispatch_request()
  File "/Users/stephentrento/flask_app/.venv/lib/python3.13/site-packages/flask/app.py", line 902, in dispatch_request
    return self.ensure_sync(self.view_functions[rule.endpoint])(**view_args)  # type: ignore[no-any-return]
           ~~~~~~~~~~~~~~~~~~~~~~~~~~~~~~~~~~~~~~~~~~~~~~~~~~~~^^^^^^^^^^^^^
  File "/Users/stephentrento/flask_app/app/routes.py", line 107, in login
    db.session.commit()
    ~~~~~~~~~~~~~~~~~^^
  File "/Users/stephentrento/flask_app/.venv/lib/python3.13/site-packages/sqlalchemy/orm/scoping.py", line 599, in commit
    return self._proxied.commit()
           ~~~~~~~~~~~~~~~~~~~~^^
  File "/Users/stephentrento/flask_app/.venv/lib/python3.13/site-packages/sqlalchemy/orm/session.py", line 2032, in commit
    trans.commit(_to_root=True)
    ~~~~~~~~~~~~^^^^^^^^^^^^^^^
  File "<string>", line 2, in commit
  File "/Users/stephentrento/flask_app/.venv/lib/python3.13/site-packages/sqlalchemy/orm/state_changes.py", line 139, in _go
    ret_value = fn(self, *arg, **kw)
  File "/Users/stephentrento/flask_app/.venv/lib/python3.13/site-packages/sqlalchemy/orm/session.py", line 1313, in commit
    self._prepare_impl()
    ~~~~~~~~~~~~~~~~~~^^
  File "<string>", line 2, in _prepare_impl
  File "/Users/stephentrento/flask_app/.venv/lib/python3.13/site-packages/sqlalchemy/orm/state_changes.py", line 139, in _go
    ret_value = fn(self, *arg, **kw)
  File "/Users/stephentrento/flask_app/.venv/lib/python3.13/site-packages/sqlalchemy/orm/session.py", line 1288, in _prepare_impl
    self.session.flush()
    ~~~~~~~~~~~~~~~~~~^^
  File "/Users/stephentrento/flask_app/.venv/lib/python3.13/site-packages/sqlalchemy/orm/session.py", line 4353, in flush
    self._flush(objects)
    ~~~~~~~~~~~^^^^^^^^^
  File "/Users/stephentrento/flask_app/.venv/lib/python3.13/site-packages/sqlalchemy/orm/session.py", line 4488, in _flush
    with util.safe_reraise():
         ~~~~~~~~~~~~~~~~~^^
  File "/Users/stephentrento/flask_app/.venv/lib/python3.13/site-packages/sqlalchemy/util/langhelpers.py", line 146, in __exit__
    raise exc_value.with_traceback(exc_tb)
  File "/Users/stephentrento/flask_app/.venv/lib/python3.13/site-packages/sqlalchemy/orm/session.py", line 4449, in _flush
    flush_context.execute()
    ~~~~~~~~~~~~~~~~~~~~~^^
  File "/Users/stephentrento/flask_app/.venv/lib/python3.13/site-packages/sqlalchemy/orm/unitofwork.py", line 466, in execute
    rec.execute(self)
    ~~~~~~~~~~~^^^^^^
  File "/Users/stephentrento/flask_app/.venv/lib/python3.13/site-packages/sqlalchemy/orm/unitofwork.py", line 642, in execute
    util.preloaded.orm_persistence.save_obj(
    ~~~~~~~~~~~~~~~~~~~~~~~~~~~~~~~~~~~~~~~^
        self.mapper,
        ^^^^^^^^^^^^
        uow.states_for_mapper_hierarchy(self.mapper, False, False),
        ^^^^^^^^^^^^^^^^^^^^^^^^^^^^^^^^^^^^^^^^^^^^^^^^^^^^^^^^^^^
        uow,
        ^^^^
    )
    ^
  File "/Users/stephentrento/flask_app/.venv/lib/python3.13/site-packages/sqlalchemy/orm/persistence.py", line 93, in save_obj
    _emit_insert_statements(
    ~~~~~~~~~~~~~~~~~~~~~~~^
        base_mapper,
        ^^^^^^^^^^^^
    ...<3 lines>...
        insert,
        ^^^^^^^
    )
    ^
  File "/Users/stephentrento/flask_app/.venv/lib/python3.13/site-packages/sqlalchemy/orm/persistence.py", line 1233, in _emit_insert_statements
    result = connection.execute(
        statement,
        params,
        execution_options=execution_options,
    )
  File "/Users/stephentrento/flask_app/.venv/lib/python3.13/site-packages/sqlalchemy/engine/base.py", line 1416, in execute
    return meth(
        self,
        distilled_parameters,
        execution_options or NO_OPTIONS,
    )
  File "/Users/stephentrento/flask_app/.venv/lib/python3.13/site-packages/sqlalchemy/sql/elements.py", line 515, in _execute_on_connection
    return connection._execute_clauseelement(
           ~~~~~~~~~~~~~~~~~~~~~~~~~~~~~~~~~^
        self, distilled_params, execution_options
        ^^^^^^^^^^^^^^^^^^^^^^^^^^^^^^^^^^^^^^^^^
    )
    ^
  File "/Users/stephentrento/flask_app/.venv/lib/python3.13/site-packages/sqlalchemy/engine/base.py", line 1638, in _execute_clauseelement
    ret = self._execute_context(
        dialect,
    ...<8 lines>...
        cache_hit=cache_hit,
    )
  File "/Users/stephentrento/flask_app/.venv/lib/python3.13/site-packages/sqlalchemy/engine/base.py", line 1843, in _execute_context
    return self._exec_single_context(
           ~~~~~~~~~~~~~~~~~~~~~~~~~^
        dialect, context, statement, parameters
        ^^^^^^^^^^^^^^^^^^^^^^^^^^^^^^^^^^^^^^^
    )
    ^
  File "/Users/stephentrento/flask_app/.venv/lib/python3.13/site-packages/sqlalchemy/engine/base.py", line 1983, in _exec_single_context
    self._handle_dbapi_exception(
    ~~~~~~~~~~~~~~~~~~~~~~~~~~~~^
        e, str_statement, effective_parameters, cursor, context
        ^^^^^^^^^^^^^^^^^^^^^^^^^^^^^^^^^^^^^^^^^^^^^^^^^^^^^^^
    )
    ^
  File "/Users/stephentrento/flask_app/.venv/lib/python3.13/site-packages/sqlalchemy/engine/base.py", line 2352, in _handle_dbapi_exception
    raise sqlalchemy_exception.with_traceback(exc_info[2]) from e
  File "/Users/stephentrento/flask_app/.venv/lib/python3.13/site-packages/sqlalchemy/engine/base.py", line 1964, in _exec_single_context
    self.dialect.do_execute(
    ~~~~~~~~~~~~~~~~~~~~~~~^
        cursor, str_statement, effective_parameters, context
        ^^^^^^^^^^^^^^^^^^^^^^^^^^^^^^^^^^^^^^^^^^^^^^^^^^^^
    )
    ^
  File "/Users/stephentrento/flask_app/.venv/lib/python3.13/site-packages/sqlalchemy/engine/default.py", line 942, in do_execute
    cursor.execute(statement, parameters)
    ~~~~~~~~~~~~~~^^^^^^^^^^^^^^^^^^^^^^^
sqlalchemy.exc.IntegrityError: (sqlite3.IntegrityError) UNIQUE constraint failed: user.username
[SQL: INSERT INTO user (access_level, username, email, password_hash, about_me, last_seen) VALUES (?, ?, ?, ?, ?, ?)]
[parameters: (2, 'StephenTrento', 'stephentrento07@icloud.com', 'scrypt:32768:8:1$lEikLk07s4xNLzrL$b27139a45181114f77cabb821b509d7b09b5693b28b85cb866177712dc81d1345fe1b3beeb39ed3891992abc97c6cd907696efbbba0565473cd05666b4cb5c09', None, '2025-01-26 14:54:42.363943')]
(Background on this error at: https://sqlalche.me/e/20/gkpj)
2025-01-26 14:58:13,420 INFO: Microblog startup [in /Users/stephentrento/flask_app/app/__init__.py:48]
2025-01-26 15:11:54,697 INFO: Microblog startup [in /Users/stephentrento/flask_app/app/__init__.py:48]
2025-01-26 15:13:04,820 INFO: Microblog startup [in /Users/stephentrento/flask_app/app/__init__.py:48]
2025-01-26 15:13:45,892 INFO: Microblog startup [in /Users/stephentrento/flask_app/app/__init__.py:48]
2025-01-26 17:40:54,127 INFO: Microblog startup [in /Users/stephentrento/flask_app/app/__init__.py:48]
2025-01-26 17:41:38,241 INFO: Microblog startup [in /Users/stephentrento/flask_app/app/__init__.py:48]
