2025-01-31 21:50:00,494 ERROR: Exception on /request_organiser [GET] [in /Users/stephentrento/flask_app/.venv/lib/python3.13/site-packages/flask/app.py:875]
Traceback (most recent call last):
  File "/Users/stephentrento/flask_app/.venv/lib/python3.13/site-packages/flask/app.py", line 1511, in wsgi_app
    response = self.full_dispatch_request()
  File "/Users/stephentrento/flask_app/.venv/lib/python3.13/site-packages/flask/app.py", line 919, in full_dispatch_request
    rv = self.handle_user_exception(e)
  File "/Users/stephentrento/flask_app/.venv/lib/python3.13/site-packages/flask/app.py", line 917, in full_dispatch_request
    rv = self.dispatch_request()
  File "/Users/stephentrento/flask_app/.venv/lib/python3.13/site-packages/flask/app.py", line 902, in dispatch_request
    return self.ensure_sync(self.view_functions[rule.endpoint])(**view_args)  # type: ignore[no-any-return]
           ~~~~~~~~~~~~~~~~~~~~~~~~~~~~~~~~~~~~~~~~~~~~~~~~~~~~^^^^^^^^^^^^^
  File "/Users/stephentrento/flask_app/.venv/lib/python3.13/site-packages/flask_login/utils.py", line 290, in decorated_view
    return current_app.ensure_sync(func)(*args, **kwargs)
           ~~~~~~~~~~~~~~~~~~~~~~~~~~~~~^^^^^^^^^^^^^^^^^
  File "/Users/stephentrento/flask_app/app/routes.py", line 44, in request_organiser
    return render_template('request_organiser.html', form=form)
  File "/Users/stephentrento/flask_app/.venv/lib/python3.13/site-packages/flask/templating.py", line 150, in render_template
    return _render(app, template, context)
  File "/Users/stephentrento/flask_app/.venv/lib/python3.13/site-packages/flask/templating.py", line 131, in _render
    rv = template.render(context)
  File "/Users/stephentrento/flask_app/.venv/lib/python3.13/site-packages/jinja2/environment.py", line 1295, in render
    self.environment.handle_exception()
    ~~~~~~~~~~~~~~~~~~~~~~~~~~~~~~~~~^^
  File "/Users/stephentrento/flask_app/.venv/lib/python3.13/site-packages/jinja2/environment.py", line 942, in handle_exception
    raise rewrite_traceback_stack(source=source)
  File "/Users/stephentrento/flask_app/app/templates/request_organiser.html", line 2, in top-level template code
    {% import "bootstrap_wtf.html" as wtf %}
    ^^^^^^^^^^^^^^^^^^^^^^^^^
  File "/Users/stephentrento/flask_app/app/templates/base.html", line 72, in top-level template code
    {% block content %}{% endblock %}
    ^^^^^^^^^^^^^^^^^^^
  File "/Users/stephentrento/flask_app/app/templates/request_organiser.html", line 9, in block 'content'
    {{ wtf.quick_form(req_form) }}
    ^^^^^^^^^^^^^^^^^^^^^
  File "/Users/stephentrento/flask_app/.venv/lib/python3.13/site-packages/jinja2/runtime.py", line 784, in _invoke
    rv = self._func(*arguments)
  File "/Users/stephentrento/flask_app/app/templates/bootstrap_wtf.html", line 53, in template
    {{ form.hidden_tag() }}
  File "/Users/stephentrento/flask_app/.venv/lib/python3.13/site-packages/jinja2/environment.py", line 490, in getattr
    return getattr(obj, attribute)
jinja2.exceptions.UndefinedError: 'req_form' is undefined
2025-01-31 21:50:03,944 ERROR: Exception on /request_organiser [GET] [in /Users/stephentrento/flask_app/.venv/lib/python3.13/site-packages/flask/app.py:875]
Traceback (most recent call last):
  File "/Users/stephentrento/flask_app/.venv/lib/python3.13/site-packages/flask/app.py", line 1511, in wsgi_app
    response = self.full_dispatch_request()
  File "/Users/stephentrento/flask_app/.venv/lib/python3.13/site-packages/flask/app.py", line 919, in full_dispatch_request
    rv = self.handle_user_exception(e)
  File "/Users/stephentrento/flask_app/.venv/lib/python3.13/site-packages/flask/app.py", line 917, in full_dispatch_request
    rv = self.dispatch_request()
  File "/Users/stephentrento/flask_app/.venv/lib/python3.13/site-packages/flask/app.py", line 902, in dispatch_request
    return self.ensure_sync(self.view_functions[rule.endpoint])(**view_args)  # type: ignore[no-any-return]
           ~~~~~~~~~~~~~~~~~~~~~~~~~~~~~~~~~~~~~~~~~~~~~~~~~~~~^^^^^^^^^^^^^
  File "/Users/stephentrento/flask_app/.venv/lib/python3.13/site-packages/flask_login/utils.py", line 290, in decorated_view
    return current_app.ensure_sync(func)(*args, **kwargs)
           ~~~~~~~~~~~~~~~~~~~~~~~~~~~~~^^^^^^^^^^^^^^^^^
  File "/Users/stephentrento/flask_app/app/routes.py", line 44, in request_organiser
    return render_template('request_organiser.html', form=form)
  File "/Users/stephentrento/flask_app/.venv/lib/python3.13/site-packages/flask/templating.py", line 150, in render_template
    return _render(app, template, context)
  File "/Users/stephentrento/flask_app/.venv/lib/python3.13/site-packages/flask/templating.py", line 131, in _render
    rv = template.render(context)
  File "/Users/stephentrento/flask_app/.venv/lib/python3.13/site-packages/jinja2/environment.py", line 1295, in render
    self.environment.handle_exception()
    ~~~~~~~~~~~~~~~~~~~~~~~~~~~~~~~~~^^
  File "/Users/stephentrento/flask_app/.venv/lib/python3.13/site-packages/jinja2/environment.py", line 942, in handle_exception
    raise rewrite_traceback_stack(source=source)
  File "/Users/stephentrento/flask_app/app/templates/request_organiser.html", line 2, in top-level template code
    {% import "bootstrap_wtf.html" as wtf %}
    ^^^^^^^^^^^^^^^^^^^^^^^^^
  File "/Users/stephentrento/flask_app/app/templates/base.html", line 72, in top-level template code
    {% block content %}{% endblock %}
    ^^^^^^^^^^^^^^^^^^^
  File "/Users/stephentrento/flask_app/app/templates/request_organiser.html", line 9, in block 'content'
    {{ wtf.quick_form(req_form) }}
    ^^^^^^^^^^^^^^^^^^^^^
  File "/Users/stephentrento/flask_app/.venv/lib/python3.13/site-packages/jinja2/runtime.py", line 784, in _invoke
    rv = self._func(*arguments)
  File "/Users/stephentrento/flask_app/app/templates/bootstrap_wtf.html", line 53, in template
    {{ form.hidden_tag() }}
  File "/Users/stephentrento/flask_app/.venv/lib/python3.13/site-packages/jinja2/environment.py", line 490, in getattr
    return getattr(obj, attribute)
jinja2.exceptions.UndefinedError: 'req_form' is undefined
2025-01-31 21:50:21,727 ERROR: Exception on /map [GET] [in /Users/stephentrento/flask_app/.venv/lib/python3.13/site-packages/flask/app.py:875]
Traceback (most recent call last):
  File "/Users/stephentrento/flask_app/.venv/lib/python3.13/site-packages/flask/app.py", line 1511, in wsgi_app
    response = self.full_dispatch_request()
  File "/Users/stephentrento/flask_app/.venv/lib/python3.13/site-packages/flask/app.py", line 919, in full_dispatch_request
    rv = self.handle_user_exception(e)
  File "/Users/stephentrento/flask_app/.venv/lib/python3.13/site-packages/flask/app.py", line 917, in full_dispatch_request
    rv = self.dispatch_request()
  File "/Users/stephentrento/flask_app/.venv/lib/python3.13/site-packages/flask/app.py", line 902, in dispatch_request
    return self.ensure_sync(self.view_functions[rule.endpoint])(**view_args)  # type: ignore[no-any-return]
           ~~~~~~~~~~~~~~~~~~~~~~~~~~~~~~~~~~~~~~~~~~~~~~~~~~~~^^^^^^^^^^^^^
  File "/Users/stephentrento/flask_app/app/routes.py", line 119, in map
    form = EventForm()
  File "/Users/stephentrento/flask_app/.venv/lib/python3.13/site-packages/wtforms/form.py", line 209, in __call__
    return type.__call__(cls, *args, **kwargs)
           ~~~~~~~~~~~~~^^^^^^^^^^^^^^^^^^^^^^
  File "/Users/stephentrento/flask_app/.venv/lib/python3.13/site-packages/flask_wtf/form.py", line 73, in __init__
    super().__init__(formdata=formdata, **kwargs)
    ~~~~~~~~~~~~~~~~^^^^^^^^^^^^^^^^^^^^^^^^^^^^^
  File "/Users/stephentrento/flask_app/.venv/lib/python3.13/site-packages/wtforms/form.py", line 281, in __init__
    super().__init__(self._unbound_fields, meta=meta_obj, prefix=prefix)
    ~~~~~~~~~~~~~~~~^^^^^^^^^^^^^^^^^^^^^^^^^^^^^^^^^^^^^^^^^^^^^^^^^^^^
  File "/Users/stephentrento/flask_app/.venv/lib/python3.13/site-packages/wtforms/form.py", line 49, in __init__
    field = meta.bind_field(self, unbound_field, options)
  File "/Users/stephentrento/flask_app/.venv/lib/python3.13/site-packages/wtforms/meta.py", line 28, in bind_field
    return unbound_field.bind(form=form, **options)
           ~~~~~~~~~~~~~~~~~~^^^^^^^^^^^^^^^^^^^^^^
  File "/Users/stephentrento/flask_app/.venv/lib/python3.13/site-packages/wtforms/fields/core.py", line 387, in bind
    return self.field_class(*self.args, **kw)
           ~~~~~~~~~~~~~~~~^^^^^^^^^^^^^^^^^^
  File "/Users/stephentrento/flask_app/.venv/lib/python3.13/site-packages/wtforms/fields/datetime.py", line 170, in __init__
    super().__init__(*args, **kwargs)
    ~~~~~~~~~~~~~~~~^^^^^^^^^^^^^^^^^
  File "/Users/stephentrento/flask_app/.venv/lib/python3.13/site-packages/wtforms/fields/datetime.py", line 30, in __init__
    super().__init__(label, validators, **kwargs)
    ~~~~~~~~~~~~~~~~^^^^^^^^^^^^^^^^^^^^^^^^^^^^^
TypeError: Field.__init__() got an unexpected keyword argument 'filter_type'
2025-01-31 22:12:58,473 INFO: Microblog startup [in /Users/stephentrento/flask_app/app/__init__.py:51]
