2025-02-01 12:06:52,006 ERROR: Exception on /request_organiser [POST] [in /Users/stephentrento/flask_app/.venv/lib/python3.13/site-packages/flask/app.py:875]
Traceback (most recent call last):
  File "/Users/stephentrento/flask_app/.venv/lib/python3.13/site-packages/flask/app.py", line 1511, in wsgi_app
    response = self.full_dispatch_request()
  File "/Users/stephentrento/flask_app/.venv/lib/python3.13/site-packages/flask/app.py", line 919, in full_dispatch_request
    rv = self.handle_user_exception(e)
  File "/Users/stephentrento/flask_app/.venv/lib/python3.13/site-packages/flask/app.py", line 917, in full_dispatch_request
    rv = self.dispatch_request()
  File "/Users/stephentrento/flask_app/.venv/lib/python3.13/site-packages/flask/app.py", line 902, in dispatch_request
    return self.ensure_sync(self.view_functions[rule.endpoint])(**view_args)  # type: ignore[no-any-return]
           ~~~~~~~~~~~~~~~~~~~~~~~~~~~~~~~~~~~~~~~~~~~~~~~~~~~~^^^^^^^^^^^^^
  File "/Users/stephentrento/flask_app/.venv/lib/python3.13/site-packages/flask_login/utils.py", line 290, in decorated_view
    return current_app.ensure_sync(func)(*args, **kwargs)
           ~~~~~~~~~~~~~~~~~~~~~~~~~~~~~^^^^^^^^^^^^^^^^^
  File "/Users/stephentrento/flask_app/app/routes.py", line 37, in request_organiser
    user_requested = Request_organiser(user_id=user.id, reason=form.reason.data)
  File "<string>", line 4, in __init__
  File "/Users/stephentrento/flask_app/.venv/lib/python3.13/site-packages/sqlalchemy/orm/state.py", line 571, in _initialize_instance
    with util.safe_reraise():
         ~~~~~~~~~~~~~~~~~^^
  File "/Users/stephentrento/flask_app/.venv/lib/python3.13/site-packages/sqlalchemy/util/langhelpers.py", line 146, in __exit__
    raise exc_value.with_traceback(exc_tb)
  File "/Users/stephentrento/flask_app/.venv/lib/python3.13/site-packages/sqlalchemy/orm/state.py", line 569, in _initialize_instance
    manager.original_init(*mixed[1:], **kwargs)
    ~~~~~~~~~~~~~~~~~~~~~^^^^^^^^^^^^^^^^^^^^^^
  File "/Users/stephentrento/flask_app/.venv/lib/python3.13/site-packages/sqlalchemy/orm/decl_base.py", line 2175, in _declarative_constructor
    raise TypeError(
        "%r is an invalid keyword argument for %s" % (k, cls_.__name__)
    )
TypeError: 'user_id' is an invalid keyword argument for Request_organiser
2025-02-01 12:09:04,859 INFO: Microblog startup [in /Users/stephentrento/flask_app/app/__init__.py:51]
2025-02-01 12:16:07,372 INFO: Microblog startup [in /Users/stephentrento/flask_app/app/__init__.py:51]
2025-02-01 12:16:38,720 ERROR: Exception on /admin-view [GET] [in /Users/stephentrento/flask_app/.venv/lib/python3.13/site-packages/flask/app.py:875]
Traceback (most recent call last):
  File "/Users/stephentrento/flask_app/.venv/lib/python3.13/site-packages/flask/app.py", line 1511, in wsgi_app
    response = self.full_dispatch_request()
  File "/Users/stephentrento/flask_app/.venv/lib/python3.13/site-packages/flask/app.py", line 919, in full_dispatch_request
    rv = self.handle_user_exception(e)
  File "/Users/stephentrento/flask_app/.venv/lib/python3.13/site-packages/flask/app.py", line 917, in full_dispatch_request
    rv = self.dispatch_request()
  File "/Users/stephentrento/flask_app/.venv/lib/python3.13/site-packages/flask/app.py", line 902, in dispatch_request
    return self.ensure_sync(self.view_functions[rule.endpoint])(**view_args)  # type: ignore[no-any-return]
           ~~~~~~~~~~~~~~~~~~~~~~~~~~~~~~~~~~~~~~~~~~~~~~~~~~~~^^^^^^^^^^^^^
  File "/Users/stephentrento/flask_app/app/routes.py", line 190, in admin_view
    return render_template('admin_view.html', users=user_data, markers=marker_data)
  File "/Users/stephentrento/flask_app/.venv/lib/python3.13/site-packages/flask/templating.py", line 150, in render_template
    return _render(app, template, context)
  File "/Users/stephentrento/flask_app/.venv/lib/python3.13/site-packages/flask/templating.py", line 131, in _render
    rv = template.render(context)
  File "/Users/stephentrento/flask_app/.venv/lib/python3.13/site-packages/jinja2/environment.py", line 1295, in render
    self.environment.handle_exception()
    ~~~~~~~~~~~~~~~~~~~~~~~~~~~~~~~~~^^
  File "/Users/stephentrento/flask_app/.venv/lib/python3.13/site-packages/jinja2/environment.py", line 942, in handle_exception
    raise rewrite_traceback_stack(source=source)
  File "/Users/stephentrento/flask_app/app/templates/admin_view.html", line 1, in top-level template code
    {% extends "base.html" %}
  File "/Users/stephentrento/flask_app/app/templates/base.html", line 81, in top-level template code
    {% block content %}{% endblock %}
    ^^^^^^^^^^^^^^^^^^^
  File "/Users/stephentrento/flask_app/app/templates/admin_view.html", line 36, in block 'content'
    <strong>{{ marker.event_name }}</strong> {% if user.access_level==2 %}(Admin){% endif %}
    ^^^^^
  File "/Users/stephentrento/flask_app/.venv/lib/python3.13/site-packages/jinja2/environment.py", line 490, in getattr
    return getattr(obj, attribute)
jinja2.exceptions.UndefinedError: 'user' is undefined
2025-02-01 12:16:52,184 ERROR: Exception on /admin-view [GET] [in /Users/stephentrento/flask_app/.venv/lib/python3.13/site-packages/flask/app.py:875]
Traceback (most recent call last):
  File "/Users/stephentrento/flask_app/.venv/lib/python3.13/site-packages/flask/app.py", line 1511, in wsgi_app
    response = self.full_dispatch_request()
  File "/Users/stephentrento/flask_app/.venv/lib/python3.13/site-packages/flask/app.py", line 919, in full_dispatch_request
    rv = self.handle_user_exception(e)
  File "/Users/stephentrento/flask_app/.venv/lib/python3.13/site-packages/flask/app.py", line 917, in full_dispatch_request
    rv = self.dispatch_request()
  File "/Users/stephentrento/flask_app/.venv/lib/python3.13/site-packages/flask/app.py", line 902, in dispatch_request
    return self.ensure_sync(self.view_functions[rule.endpoint])(**view_args)  # type: ignore[no-any-return]
           ~~~~~~~~~~~~~~~~~~~~~~~~~~~~~~~~~~~~~~~~~~~~~~~~~~~~^^^^^^^^^^^^^
  File "/Users/stephentrento/flask_app/app/routes.py", line 190, in admin_view
    return render_template('admin_view.html', users=user_data, markers=marker_data)
  File "/Users/stephentrento/flask_app/.venv/lib/python3.13/site-packages/flask/templating.py", line 150, in render_template
    return _render(app, template, context)
  File "/Users/stephentrento/flask_app/.venv/lib/python3.13/site-packages/flask/templating.py", line 131, in _render
    rv = template.render(context)
  File "/Users/stephentrento/flask_app/.venv/lib/python3.13/site-packages/jinja2/environment.py", line 1295, in render
    self.environment.handle_exception()
    ~~~~~~~~~~~~~~~~~~~~~~~~~~~~~~~~~^^
  File "/Users/stephentrento/flask_app/.venv/lib/python3.13/site-packages/jinja2/environment.py", line 942, in handle_exception
    raise rewrite_traceback_stack(source=source)
  File "/Users/stephentrento/flask_app/app/templates/admin_view.html", line 1, in top-level template code
    {% extends "base.html" %}
  File "/Users/stephentrento/flask_app/app/templates/base.html", line 81, in top-level template code
    {% block content %}{% endblock %}
    ^^^^^^^^^^^^^^^^^^^
  File "/Users/stephentrento/flask_app/app/templates/admin_view.html", line 36, in block 'content'
    <strong>{{ marker.event_name }}</strong> {% if user.access_level==2 %}(Admin){% endif %}
    ^^^^^
  File "/Users/stephentrento/flask_app/.venv/lib/python3.13/site-packages/jinja2/environment.py", line 490, in getattr
    return getattr(obj, attribute)
jinja2.exceptions.UndefinedError: 'user' is undefined
2025-02-01 12:16:53,428 ERROR: Exception on /admin-view [GET] [in /Users/stephentrento/flask_app/.venv/lib/python3.13/site-packages/flask/app.py:875]
Traceback (most recent call last):
  File "/Users/stephentrento/flask_app/.venv/lib/python3.13/site-packages/flask/app.py", line 1511, in wsgi_app
    response = self.full_dispatch_request()
  File "/Users/stephentrento/flask_app/.venv/lib/python3.13/site-packages/flask/app.py", line 919, in full_dispatch_request
    rv = self.handle_user_exception(e)
  File "/Users/stephentrento/flask_app/.venv/lib/python3.13/site-packages/flask/app.py", line 917, in full_dispatch_request
    rv = self.dispatch_request()
  File "/Users/stephentrento/flask_app/.venv/lib/python3.13/site-packages/flask/app.py", line 902, in dispatch_request
    return self.ensure_sync(self.view_functions[rule.endpoint])(**view_args)  # type: ignore[no-any-return]
           ~~~~~~~~~~~~~~~~~~~~~~~~~~~~~~~~~~~~~~~~~~~~~~~~~~~~^^^^^^^^^^^^^
  File "/Users/stephentrento/flask_app/app/routes.py", line 190, in admin_view
    return render_template('admin_view.html', users=user_data, markers=marker_data)
  File "/Users/stephentrento/flask_app/.venv/lib/python3.13/site-packages/flask/templating.py", line 150, in render_template
    return _render(app, template, context)
  File "/Users/stephentrento/flask_app/.venv/lib/python3.13/site-packages/flask/templating.py", line 131, in _render
    rv = template.render(context)
  File "/Users/stephentrento/flask_app/.venv/lib/python3.13/site-packages/jinja2/environment.py", line 1295, in render
    self.environment.handle_exception()
    ~~~~~~~~~~~~~~~~~~~~~~~~~~~~~~~~~^^
  File "/Users/stephentrento/flask_app/.venv/lib/python3.13/site-packages/jinja2/environment.py", line 942, in handle_exception
    raise rewrite_traceback_stack(source=source)
  File "/Users/stephentrento/flask_app/app/templates/admin_view.html", line 1, in top-level template code
    {% extends "base.html" %}
  File "/Users/stephentrento/flask_app/app/templates/base.html", line 81, in top-level template code
    {% block content %}{% endblock %}
    ^^^^^^^^^^^^^^^^^^^
  File "/Users/stephentrento/flask_app/app/templates/admin_view.html", line 36, in block 'content'
    <strong>{{ marker.event_name }}</strong> {% if user.access_level==2 %}(Admin){% endif %}
    ^^^^^
  File "/Users/stephentrento/flask_app/.venv/lib/python3.13/site-packages/jinja2/environment.py", line 490, in getattr
    return getattr(obj, attribute)
jinja2.exceptions.UndefinedError: 'user' is undefined
2025-02-01 12:51:50,904 INFO: Microblog startup [in /Users/stephentrento/flask_app/app/__init__.py:51]
