2025-01-26 23:02:28,197 INFO: Microblog startup [in /Users/stephentrento/flask_app/app/__init__.py:48]
2025-01-26 23:02:31,101 ERROR: Exception on /request_organiser [GET] [in /Users/stephentrento/flask_app/.venv/lib/python3.13/site-packages/flask/app.py:875]
Traceback (most recent call last):
  File "/Users/stephentrento/flask_app/.venv/lib/python3.13/site-packages/flask/app.py", line 1511, in wsgi_app
    response = self.full_dispatch_request()
  File "/Users/stephentrento/flask_app/.venv/lib/python3.13/site-packages/flask/app.py", line 919, in full_dispatch_request
    rv = self.handle_user_exception(e)
  File "/Users/stephentrento/flask_app/.venv/lib/python3.13/site-packages/flask/app.py", line 917, in full_dispatch_request
    rv = self.dispatch_request()
  File "/Users/stephentrento/flask_app/.venv/lib/python3.13/site-packages/flask/app.py", line 902, in dispatch_request
    return self.ensure_sync(self.view_functions[rule.endpoint])(**view_args)  # type: ignore[no-any-return]
           ~~~~~~~~~~~~~~~~~~~~~~~~~~~~~~~~~~~~~~~~~~~~~~~~~~~~^^^^^^^^^^^^^
  File "/Users/stephentrento/flask_app/.venv/lib/python3.13/site-packages/flask_login/utils.py", line 290, in decorated_view
    return current_app.ensure_sync(func)(*args, **kwargs)
           ~~~~~~~~~~~~~~~~~~~~~~~~~~~~~^^^^^^^^^^^^^^^^^
  File "/Users/stephentrento/flask_app/app/routes.py", line 25, in request_organiser
    if form.validate_on_submit(): #If user fills in form properly
       ^^^^^^^^^^^^^^^^^^^^^^^
AttributeError: 'RequestOrganiserForm' object has no attribute 'validate_on_submit'
2025-01-26 23:03:40,170 INFO: Microblog startup [in /Users/stephentrento/flask_app/app/__init__.py:48]
2025-01-26 23:03:44,684 ERROR: Exception on /request_organiser [GET] [in /Users/stephentrento/flask_app/.venv/lib/python3.13/site-packages/flask/app.py:875]
Traceback (most recent call last):
  File "/Users/stephentrento/flask_app/.venv/lib/python3.13/site-packages/flask/app.py", line 1511, in wsgi_app
    response = self.full_dispatch_request()
  File "/Users/stephentrento/flask_app/.venv/lib/python3.13/site-packages/flask/app.py", line 919, in full_dispatch_request
    rv = self.handle_user_exception(e)
  File "/Users/stephentrento/flask_app/.venv/lib/python3.13/site-packages/flask/app.py", line 917, in full_dispatch_request
    rv = self.dispatch_request()
  File "/Users/stephentrento/flask_app/.venv/lib/python3.13/site-packages/flask/app.py", line 902, in dispatch_request
    return self.ensure_sync(self.view_functions[rule.endpoint])(**view_args)  # type: ignore[no-any-return]
           ~~~~~~~~~~~~~~~~~~~~~~~~~~~~~~~~~~~~~~~~~~~~~~~~~~~~^^^^^^^^^^^^^
  File "/Users/stephentrento/flask_app/.venv/lib/python3.13/site-packages/flask_login/utils.py", line 290, in decorated_view
    return current_app.ensure_sync(func)(*args, **kwargs)
           ~~~~~~~~~~~~~~~~~~~~~~~~~~~~~^^^^^^^^^^^^^^^^^
  File "/Users/stephentrento/flask_app/app/routes.py", line 25, in request_organiser
    if form.validate_on_submit(): #If user fills in form properly
       ^^^^^^^^^^^^^^^^^^^^^^^
AttributeError: 'RequestOrganiserForm' object has no attribute 'validate_on_submit'
2025-01-26 23:08:47,439 INFO: Microblog startup [in /Users/stephentrento/flask_app/app/__init__.py:48]
2025-01-26 23:08:50,740 ERROR: Exception on /request_organiser [GET] [in /Users/stephentrento/flask_app/.venv/lib/python3.13/site-packages/flask/app.py:875]
Traceback (most recent call last):
  File "/Users/stephentrento/flask_app/.venv/lib/python3.13/site-packages/flask/app.py", line 1511, in wsgi_app
    response = self.full_dispatch_request()
  File "/Users/stephentrento/flask_app/.venv/lib/python3.13/site-packages/flask/app.py", line 919, in full_dispatch_request
    rv = self.handle_user_exception(e)
  File "/Users/stephentrento/flask_app/.venv/lib/python3.13/site-packages/flask/app.py", line 917, in full_dispatch_request
    rv = self.dispatch_request()
  File "/Users/stephentrento/flask_app/.venv/lib/python3.13/site-packages/flask/app.py", line 902, in dispatch_request
    return self.ensure_sync(self.view_functions[rule.endpoint])(**view_args)  # type: ignore[no-any-return]
           ~~~~~~~~~~~~~~~~~~~~~~~~~~~~~~~~~~~~~~~~~~~~~~~~~~~~^^^^^^^^^^^^^
  File "/Users/stephentrento/flask_app/.venv/lib/python3.13/site-packages/flask_login/utils.py", line 290, in decorated_view
    return current_app.ensure_sync(func)(*args, **kwargs)
           ~~~~~~~~~~~~~~~~~~~~~~~~~~~~~^^^^^^^^^^^^^^^^^
  File "/Users/stephentrento/flask_app/app/routes.py", line 32, in request_organiser
    return render_template('request_organiser.html', form=form)
  File "/Users/stephentrento/flask_app/.venv/lib/python3.13/site-packages/flask/templating.py", line 150, in render_template
    return _render(app, template, context)
  File "/Users/stephentrento/flask_app/.venv/lib/python3.13/site-packages/flask/templating.py", line 131, in _render
    rv = template.render(context)
  File "/Users/stephentrento/flask_app/.venv/lib/python3.13/site-packages/jinja2/environment.py", line 1295, in render
    self.environment.handle_exception()
    ~~~~~~~~~~~~~~~~~~~~~~~~~~~~~~~~~^^
  File "/Users/stephentrento/flask_app/.venv/lib/python3.13/site-packages/jinja2/environment.py", line 942, in handle_exception
    raise rewrite_traceback_stack(source=source)
  File "/Users/stephentrento/flask_app/app/templates/request_organiser.html", line 1, in top-level template code
    {% extends "base.html" %}
  File "/Users/stephentrento/flask_app/app/templates/base.html", line 76, in top-level template code
    {% block content %}{% endblock %}
    ^^^^^^^^^^^^^^^^^^^
  File "/Users/stephentrento/flask_app/app/templates/request_organiser.html", line 8, in block 'content'
    {{ wtf.quick_form(form) }}
    ^^^^^^^^^^^^^^^^^^^^^
  File "/Users/stephentrento/flask_app/.venv/lib/python3.13/site-packages/jinja2/environment.py", line 490, in getattr
    return getattr(obj, attribute)
jinja2.exceptions.UndefinedError: 'wtf' is undefined
2025-01-26 23:10:02,034 ERROR: Exception on /reset_password_request [POST] [in /Users/stephentrento/flask_app/.venv/lib/python3.13/site-packages/flask/app.py:875]
Traceback (most recent call last):
  File "/Users/stephentrento/flask_app/.venv/lib/python3.13/site-packages/flask/app.py", line 1511, in wsgi_app
    response = self.full_dispatch_request()
  File "/Users/stephentrento/flask_app/.venv/lib/python3.13/site-packages/flask/app.py", line 919, in full_dispatch_request
    rv = self.handle_user_exception(e)
  File "/Users/stephentrento/flask_app/.venv/lib/python3.13/site-packages/flask/app.py", line 917, in full_dispatch_request
    rv = self.dispatch_request()
  File "/Users/stephentrento/flask_app/.venv/lib/python3.13/site-packages/flask/app.py", line 902, in dispatch_request
    return self.ensure_sync(self.view_functions[rule.endpoint])(**view_args)  # type: ignore[no-any-return]
           ~~~~~~~~~~~~~~~~~~~~~~~~~~~~~~~~~~~~~~~~~~~~~~~~~~~~^^^^^^^^^^^^^
  File "/Users/stephentrento/flask_app/app/routes.py", line 167, in reset_password_request
    send_password_reset_email(user) # if there is such an email given by the user, send an automated email
    ~~~~~~~~~~~~~~~~~~~~~~~~~^^^^^^
  File "/Users/stephentrento/flask_app/app/email.py", line 20, in send_password_reset_email
    token = user.get_reset_password_token()
  File "/Users/stephentrento/flask_app/app/models.py", line 109, in get_reset_password_token
    return jwt.encode(
           ^^^^^^^^^^
AttributeError: module 'jwt' has no attribute 'encode'
2025-01-27 00:32:21,395 INFO: Microblog startup [in /Users/stephentrento/flask_app/app/__init__.py:48]
2025-01-27 00:36:30,060 INFO: Microblog startup [in /Users/stephentrento/flask_app/app/__init__.py:48]
2025-01-27 00:37:07,504 INFO: Microblog startup [in /Users/stephentrento/flask_app/app/__init__.py:48]
2025-01-27 00:37:30,290 INFO: Microblog startup [in /Users/stephentrento/flask_app/app/__init__.py:48]
2025-01-27 00:40:58,082 INFO: Microblog startup [in /Users/stephentrento/flask_app/app/__init__.py:48]
