2025-01-23 23:06:21,186 ERROR: Exception on /map [GET] [in /Users/stephentrento/flask_app/.venv/lib/python3.13/site-packages/flask/app.py:875]
Traceback (most recent call last):
  File "/Users/stephentrento/flask_app/.venv/lib/python3.13/site-packages/flask/app.py", line 1511, in wsgi_app
    response = self.full_dispatch_request()
  File "/Users/stephentrento/flask_app/.venv/lib/python3.13/site-packages/flask/app.py", line 919, in full_dispatch_request
    rv = self.handle_user_exception(e)
  File "/Users/stephentrento/flask_app/.venv/lib/python3.13/site-packages/flask/app.py", line 917, in full_dispatch_request
    rv = self.dispatch_request()
  File "/Users/stephentrento/flask_app/.venv/lib/python3.13/site-packages/flask/app.py", line 902, in dispatch_request
    return self.ensure_sync(self.view_functions[rule.endpoint])(**view_args)  # type: ignore[no-any-return]
           ~~~~~~~~~~~~~~~~~~~~~~~~~~~~~~~~~~~~~~~~~~~~~~~~~~~~^^^^^^^^^^^^^
  File "/Users/stephentrento/flask_app/app/routes.py", line 61, in map
    return render_template('map.html', form=form, markers=jsonify(markers))
                                                          ~~~~~~~^^^^^^^^^
  File "/Users/stephentrento/flask_app/.venv/lib/python3.13/site-packages/flask/json/__init__.py", line 170, in jsonify
    return current_app.json.response(*args, **kwargs)  # type: ignore[return-value]
           ~~~~~~~~~~~~~~~~~~~~~~~~~^^^^^^^^^^^^^^^^^
  File "/Users/stephentrento/flask_app/.venv/lib/python3.13/site-packages/flask/json/provider.py", line 214, in response
    f"{self.dumps(obj, **dump_args)}\n", mimetype=self.mimetype
       ~~~~~~~~~~^^^^^^^^^^^^^^^^^^
  File "/Users/stephentrento/flask_app/.venv/lib/python3.13/site-packages/flask/json/provider.py", line 179, in dumps
    return json.dumps(obj, **kwargs)
           ~~~~~~~~~~^^^^^^^^^^^^^^^
  File "/opt/homebrew/Cellar/python@3.13/3.13.0_1/Frameworks/Python.framework/Versions/3.13/lib/python3.13/json/__init__.py", line 238, in dumps
    **kw).encode(obj)
          ~~~~~~^^^^^
  File "/opt/homebrew/Cellar/python@3.13/3.13.0_1/Frameworks/Python.framework/Versions/3.13/lib/python3.13/json/encoder.py", line 200, in encode
    chunks = self.iterencode(o, _one_shot=True)
  File "/opt/homebrew/Cellar/python@3.13/3.13.0_1/Frameworks/Python.framework/Versions/3.13/lib/python3.13/json/encoder.py", line 261, in iterencode
    return _iterencode(o, 0)
  File "/Users/stephentrento/flask_app/.venv/lib/python3.13/site-packages/flask/json/provider.py", line 121, in _default
    raise TypeError(f"Object of type {type(o).__name__} is not JSON serializable")
TypeError: Object of type Response is not JSON serializable
2025-01-23 23:07:25,094 INFO: Microblog startup [in /Users/stephentrento/flask_app/app/__init__.py:48]
2025-01-23 23:07:28,522 ERROR: Exception on /map [GET] [in /Users/stephentrento/flask_app/.venv/lib/python3.13/site-packages/flask/app.py:875]
Traceback (most recent call last):
  File "/Users/stephentrento/flask_app/.venv/lib/python3.13/site-packages/flask/app.py", line 1511, in wsgi_app
    response = self.full_dispatch_request()
  File "/Users/stephentrento/flask_app/.venv/lib/python3.13/site-packages/flask/app.py", line 919, in full_dispatch_request
    rv = self.handle_user_exception(e)
  File "/Users/stephentrento/flask_app/.venv/lib/python3.13/site-packages/flask/app.py", line 917, in full_dispatch_request
    rv = self.dispatch_request()
  File "/Users/stephentrento/flask_app/.venv/lib/python3.13/site-packages/flask/app.py", line 902, in dispatch_request
    return self.ensure_sync(self.view_functions[rule.endpoint])(**view_args)  # type: ignore[no-any-return]
           ~~~~~~~~~~~~~~~~~~~~~~~~~~~~~~~~~~~~~~~~~~~~~~~~~~~~^^^^^^^^^^^^^
  File "/Users/stephentrento/flask_app/app/routes.py", line 61, in map
    return render_template('map.html', form=form, markers=jsonify(markers))
                                                          ~~~~~~~^^^^^^^^^
  File "/Users/stephentrento/flask_app/.venv/lib/python3.13/site-packages/flask/json/__init__.py", line 170, in jsonify
    return current_app.json.response(*args, **kwargs)  # type: ignore[return-value]
           ~~~~~~~~~~~~~~~~~~~~~~~~~^^^^^^^^^^^^^^^^^
  File "/Users/stephentrento/flask_app/.venv/lib/python3.13/site-packages/flask/json/provider.py", line 214, in response
    f"{self.dumps(obj, **dump_args)}\n", mimetype=self.mimetype
       ~~~~~~~~~~^^^^^^^^^^^^^^^^^^
  File "/Users/stephentrento/flask_app/.venv/lib/python3.13/site-packages/flask/json/provider.py", line 179, in dumps
    return json.dumps(obj, **kwargs)
           ~~~~~~~~~~^^^^^^^^^^^^^^^
  File "/opt/homebrew/Cellar/python@3.13/3.13.0_1/Frameworks/Python.framework/Versions/3.13/lib/python3.13/json/__init__.py", line 238, in dumps
    **kw).encode(obj)
          ~~~~~~^^^^^
  File "/opt/homebrew/Cellar/python@3.13/3.13.0_1/Frameworks/Python.framework/Versions/3.13/lib/python3.13/json/encoder.py", line 200, in encode
    chunks = self.iterencode(o, _one_shot=True)
  File "/opt/homebrew/Cellar/python@3.13/3.13.0_1/Frameworks/Python.framework/Versions/3.13/lib/python3.13/json/encoder.py", line 261, in iterencode
    return _iterencode(o, 0)
  File "/Users/stephentrento/flask_app/.venv/lib/python3.13/site-packages/flask/json/provider.py", line 121, in _default
    raise TypeError(f"Object of type {type(o).__name__} is not JSON serializable")
TypeError: Object of type Response is not JSON serializable
2025-01-23 23:08:05,764 INFO: Microblog startup [in /Users/stephentrento/flask_app/app/__init__.py:48]
2025-01-23 23:11:10,030 INFO: Microblog startup [in /Users/stephentrento/flask_app/app/__init__.py:48]
2025-01-23 23:13:59,645 INFO: Microblog startup [in /Users/stephentrento/flask_app/app/__init__.py:48]
2025-01-23 23:20:00,416 INFO: Microblog startup [in /Users/stephentrento/flask_app/app/__init__.py:48]
2025-01-24 09:40:16,307 INFO: Microblog startup [in /Users/stephentrento/flask_app/app/__init__.py:48]
2025-01-24 09:40:31,352 ERROR: Exception on / [POST] [in /Users/stephentrento/flask_app/.venv/lib/python3.13/site-packages/flask/app.py:875]
Traceback (most recent call last):
  File "/Users/stephentrento/flask_app/app/routes.py", line 26, in index
    language = detect(form.post.data)
               ^^^^^^
NameError: name 'detect' is not defined

During handling of the above exception, another exception occurred:

Traceback (most recent call last):
  File "/Users/stephentrento/flask_app/.venv/lib/python3.13/site-packages/flask/app.py", line 1511, in wsgi_app
    response = self.full_dispatch_request()
  File "/Users/stephentrento/flask_app/.venv/lib/python3.13/site-packages/flask/app.py", line 919, in full_dispatch_request
    rv = self.handle_user_exception(e)
  File "/Users/stephentrento/flask_app/.venv/lib/python3.13/site-packages/flask/app.py", line 917, in full_dispatch_request
    rv = self.dispatch_request()
  File "/Users/stephentrento/flask_app/.venv/lib/python3.13/site-packages/flask/app.py", line 902, in dispatch_request
    return self.ensure_sync(self.view_functions[rule.endpoint])(**view_args)  # type: ignore[no-any-return]
           ~~~~~~~~~~~~~~~~~~~~~~~~~~~~~~~~~~~~~~~~~~~~~~~~~~~~^^^^^^^^^^^^^
  File "/Users/stephentrento/flask_app/.venv/lib/python3.13/site-packages/flask_login/utils.py", line 290, in decorated_view
    return current_app.ensure_sync(func)(*args, **kwargs)
           ~~~~~~~~~~~~~~~~~~~~~~~~~~~~~^^^^^^^^^^^^^^^^^
  File "/Users/stephentrento/flask_app/app/routes.py", line 27, in index
    except LangDetectException:
           ^^^^^^^^^^^^^^^^^^^
NameError: name 'LangDetectException' is not defined
2025-01-24 09:41:37,053 INFO: Microblog startup [in /Users/stephentrento/flask_app/app/__init__.py:48]
2025-01-24 09:41:41,191 ERROR: Exception on / [POST] [in /Users/stephentrento/flask_app/.venv/lib/python3.13/site-packages/flask/app.py:875]
Traceback (most recent call last):
  File "/Users/stephentrento/flask_app/.venv/lib/python3.13/site-packages/flask/app.py", line 1511, in wsgi_app
    response = self.full_dispatch_request()
  File "/Users/stephentrento/flask_app/.venv/lib/python3.13/site-packages/flask/app.py", line 919, in full_dispatch_request
    rv = self.handle_user_exception(e)
  File "/Users/stephentrento/flask_app/.venv/lib/python3.13/site-packages/flask/app.py", line 917, in full_dispatch_request
    rv = self.dispatch_request()
  File "/Users/stephentrento/flask_app/.venv/lib/python3.13/site-packages/flask/app.py", line 902, in dispatch_request
    return self.ensure_sync(self.view_functions[rule.endpoint])(**view_args)  # type: ignore[no-any-return]
           ~~~~~~~~~~~~~~~~~~~~~~~~~~~~~~~~~~~~~~~~~~~~~~~~~~~~^^^^^^^^^^^^^
  File "/Users/stephentrento/flask_app/.venv/lib/python3.13/site-packages/flask_login/utils.py", line 290, in decorated_view
    return current_app.ensure_sync(func)(*args, **kwargs)
           ~~~~~~~~~~~~~~~~~~~~~~~~~~~~~^^^^^^^^^^^^^^^^^
  File "/Users/stephentrento/flask_app/app/routes.py", line 25, in index
    post = Post(body=form.post.data, author=current_user, language=language) #add a new record in the post db with the data in the form
                                                                   ^^^^^^^^
NameError: name 'language' is not defined
