2025-02-23 22:51:28,757 ERROR: Exception on /explore [GET] [in /Users/stephentrento/flask_app/.venv/lib/python3.13/site-packages/flask/app.py:875]
Traceback (most recent call last):
  File "/Users/stephentrento/flask_app/.venv/lib/python3.13/site-packages/flask/app.py", line 1511, in wsgi_app
    response = self.full_dispatch_request()
  File "/Users/stephentrento/flask_app/.venv/lib/python3.13/site-packages/flask/app.py", line 919, in full_dispatch_request
    rv = self.handle_user_exception(e)
  File "/Users/stephentrento/flask_app/.venv/lib/python3.13/site-packages/flask/app.py", line 917, in full_dispatch_request
    rv = self.dispatch_request()
  File "/Users/stephentrento/flask_app/.venv/lib/python3.13/site-packages/flask/app.py", line 902, in dispatch_request
    return self.ensure_sync(self.view_functions[rule.endpoint])(**view_args)  # type: ignore[no-any-return]
           ~~~~~~~~~~~~~~~~~~~~~~~~~~~~~~~~~~~~~~~~~~~~~~~~~~~~^^^^^^^^^^^^^
  File "/Users/stephentrento/flask_app/.venv/lib/python3.13/site-packages/flask_login/utils.py", line 290, in decorated_view
    return current_app.ensure_sync(func)(*args, **kwargs)
           ~~~~~~~~~~~~~~~~~~~~~~~~~~~~~^^^^^^^^^^^^^^^^^
  File "/Users/stephentrento/flask_app/app/routes.py", line 287, in explore
    search_results = search_posts_and_users(user_asks) # filter the search for the query
  File "/Users/stephentrento/flask_app/app/routes.py", line 317, in search_posts_and_users
    user_posts = Post.query.filter(Post.author.in_([user.id for user in user_results])).all()
                                   ~~~~~~~~~~~~~~~^^^^^^^^^^^^^^^^^^^^^^^^^^^^^^^^^^^^
  File "/Users/stephentrento/flask_app/.venv/lib/python3.13/site-packages/sqlalchemy/sql/operators.py", line 943, in in_
    return self.operate(in_op, other)
           ~~~~~~~~~~~~^^^^^^^^^^^^^^
  File "/Users/stephentrento/flask_app/.venv/lib/python3.13/site-packages/sqlalchemy/orm/attributes.py", line 453, in operate
    return op(self.comparator, *other, **kwargs)  # type: ignore[no-any-return]  # noqa: E501
  File "/Users/stephentrento/flask_app/.venv/lib/python3.13/site-packages/sqlalchemy/sql/operators.py", line 2146, in in_op
    return a.in_(b)
           ~~~~~^^^
  File "/Users/stephentrento/flask_app/.venv/lib/python3.13/site-packages/sqlalchemy/orm/relationships.py", line 699, in in_
    raise NotImplementedError(
    ...<4 lines>...
    )
NotImplementedError: in_() not yet supported for relationships.  For a simple many-to-one, use in_() against the set of foreign key values.
2025-02-23 22:53:32,608 INFO: Our Camden startup [in /Users/stephentrento/flask_app/app/__init__.py:51]
