2025-02-22 22:48:03,228 ERROR: Exception on /explore [GET] [in /Users/stephentrento/flask_app/.venv/lib/python3.13/site-packages/flask/app.py:875]
Traceback (most recent call last):
  File "/Users/stephentrento/flask_app/.venv/lib/python3.13/site-packages/flask/app.py", line 1511, in wsgi_app
    response = self.full_dispatch_request()
  File "/Users/stephentrento/flask_app/.venv/lib/python3.13/site-packages/flask/app.py", line 919, in full_dispatch_request
    rv = self.handle_user_exception(e)
  File "/Users/stephentrento/flask_app/.venv/lib/python3.13/site-packages/flask/app.py", line 917, in full_dispatch_request
    rv = self.dispatch_request()
  File "/Users/stephentrento/flask_app/.venv/lib/python3.13/site-packages/flask/app.py", line 902, in dispatch_request
    return self.ensure_sync(self.view_functions[rule.endpoint])(**view_args)  # type: ignore[no-any-return]
           ~~~~~~~~~~~~~~~~~~~~~~~~~~~~~~~~~~~~~~~~~~~~~~~~~~~~^^^^^^^^^^^^^
  File "/Users/stephentrento/flask_app/.venv/lib/python3.13/site-packages/flask_login/utils.py", line 290, in decorated_view
    return current_app.ensure_sync(func)(*args, **kwargs)
           ~~~~~~~~~~~~~~~~~~~~~~~~~~~~~^^^^^^^^^^^^^^^^^
  File "/Users/stephentrento/flask_app/app/routes.py", line 263, in explore
    posts = db.paginate(search_results, page=page,
                    per_page=app.config['POSTS_PER_PAGE'], error_out=False) # paginate posts, with descending order of time
  File "/Users/stephentrento/flask_app/.venv/lib/python3.13/site-packages/flask_sqlalchemy/extension.py", line 839, in paginate
    return SelectPagination(
        select=select,
    ...<5 lines>...
        count=count,
    )
  File "/Users/stephentrento/flask_app/.venv/lib/python3.13/site-packages/flask_sqlalchemy/pagination.py", line 72, in __init__
    items = self._query_items()
  File "/Users/stephentrento/flask_app/.venv/lib/python3.13/site-packages/flask_sqlalchemy/pagination.py", line 337, in _query_items
    select = select.limit(self.per_page).offset(self._query_offset)
             ^^^^^^^^^^^^
AttributeError: 'list' object has no attribute 'limit'
2025-02-22 22:49:08,040 INFO: Our Camden startup [in /Users/stephentrento/flask_app/app/__init__.py:51]
2025-02-22 22:49:14,623 ERROR: Exception on /explore [GET] [in /Users/stephentrento/flask_app/.venv/lib/python3.13/site-packages/flask/app.py:875]
Traceback (most recent call last):
  File "/Users/stephentrento/flask_app/.venv/lib/python3.13/site-packages/flask/app.py", line 1511, in wsgi_app
    response = self.full_dispatch_request()
  File "/Users/stephentrento/flask_app/.venv/lib/python3.13/site-packages/flask/app.py", line 919, in full_dispatch_request
    rv = self.handle_user_exception(e)
  File "/Users/stephentrento/flask_app/.venv/lib/python3.13/site-packages/flask/app.py", line 917, in full_dispatch_request
    rv = self.dispatch_request()
  File "/Users/stephentrento/flask_app/.venv/lib/python3.13/site-packages/flask/app.py", line 902, in dispatch_request
    return self.ensure_sync(self.view_functions[rule.endpoint])(**view_args)  # type: ignore[no-any-return]
           ~~~~~~~~~~~~~~~~~~~~~~~~~~~~~~~~~~~~~~~~~~~~~~~~~~~~^^^^^^^^^^^^^
  File "/Users/stephentrento/flask_app/.venv/lib/python3.13/site-packages/flask_login/utils.py", line 290, in decorated_view
    return current_app.ensure_sync(func)(*args, **kwargs)
           ~~~~~~~~~~~~~~~~~~~~~~~~~~~~~^^^^^^^^^^^^^^^^^
  File "/Users/stephentrento/flask_app/app/routes.py", line 263, in explore
    posts = search_results[(page - 1) * per_page: page * per_page]
                                        ^^^^^^^^
NameError: name 'per_page' is not defined
2025-02-22 22:50:11,666 INFO: Our Camden startup [in /Users/stephentrento/flask_app/app/__init__.py:51]
2025-02-22 22:50:22,609 ERROR: Exception on /explore [GET] [in /Users/stephentrento/flask_app/.venv/lib/python3.13/site-packages/flask/app.py:875]
Traceback (most recent call last):
  File "/Users/stephentrento/flask_app/.venv/lib/python3.13/site-packages/flask/app.py", line 1511, in wsgi_app
    response = self.full_dispatch_request()
  File "/Users/stephentrento/flask_app/.venv/lib/python3.13/site-packages/flask/app.py", line 919, in full_dispatch_request
    rv = self.handle_user_exception(e)
  File "/Users/stephentrento/flask_app/.venv/lib/python3.13/site-packages/flask/app.py", line 917, in full_dispatch_request
    rv = self.dispatch_request()
  File "/Users/stephentrento/flask_app/.venv/lib/python3.13/site-packages/flask/app.py", line 902, in dispatch_request
    return self.ensure_sync(self.view_functions[rule.endpoint])(**view_args)  # type: ignore[no-any-return]
           ~~~~~~~~~~~~~~~~~~~~~~~~~~~~~~~~~~~~~~~~~~~~~~~~~~~~^^^^^^^^^^^^^
  File "/Users/stephentrento/flask_app/.venv/lib/python3.13/site-packages/flask_login/utils.py", line 290, in decorated_view
    return current_app.ensure_sync(func)(*args, **kwargs)
           ~~~~~~~~~~~~~~~~~~~~~~~~~~~~~^^^^^^^^^^^^^^^^^
  File "/Users/stephentrento/flask_app/app/routes.py", line 263, in explore
    posts = search_results[(page - 1) * app.config['POSTS_PER_PAGE'],: page * per_page]
                                                                              ^^^^^^^^
NameError: name 'per_page' is not defined
2025-02-22 22:50:40,661 INFO: Our Camden startup [in /Users/stephentrento/flask_app/app/__init__.py:51]
2025-02-22 22:50:46,427 INFO: Our Camden startup [in /Users/stephentrento/flask_app/app/__init__.py:51]
2025-02-22 22:51:28,391 INFO: Our Camden startup [in /Users/stephentrento/flask_app/app/__init__.py:51]
2025-02-22 22:51:45,597 INFO: Our Camden startup [in /Users/stephentrento/flask_app/app/__init__.py:51]
2025-02-22 22:51:53,434 ERROR: Exception on /explore [GET] [in /Users/stephentrento/flask_app/.venv/lib/python3.13/site-packages/flask/app.py:875]
Traceback (most recent call last):
  File "/Users/stephentrento/flask_app/.venv/lib/python3.13/site-packages/flask/app.py", line 1511, in wsgi_app
    response = self.full_dispatch_request()
  File "/Users/stephentrento/flask_app/.venv/lib/python3.13/site-packages/flask/app.py", line 919, in full_dispatch_request
    rv = self.handle_user_exception(e)
  File "/Users/stephentrento/flask_app/.venv/lib/python3.13/site-packages/flask/app.py", line 917, in full_dispatch_request
    rv = self.dispatch_request()
  File "/Users/stephentrento/flask_app/.venv/lib/python3.13/site-packages/flask/app.py", line 902, in dispatch_request
    return self.ensure_sync(self.view_functions[rule.endpoint])(**view_args)  # type: ignore[no-any-return]
           ~~~~~~~~~~~~~~~~~~~~~~~~~~~~~~~~~~~~~~~~~~~~~~~~~~~~^^^^^^^^^^^^^
  File "/Users/stephentrento/flask_app/.venv/lib/python3.13/site-packages/flask_login/utils.py", line 290, in decorated_view
    return current_app.ensure_sync(func)(*args, **kwargs)
           ~~~~~~~~~~~~~~~~~~~~~~~~~~~~~^^^^^^^^^^^^^^^^^
  File "/Users/stephentrento/flask_app/app/routes.py", line 263, in explore
    posts = search_results[(page - 1) * app.config['POSTS_PER_PAGE'],: page * per_page]
                                                                              ^^^^^^^^
NameError: name 'per_page' is not defined
2025-02-22 22:52:16,910 INFO: Our Camden startup [in /Users/stephentrento/flask_app/app/__init__.py:51]
2025-02-22 22:52:23,057 ERROR: Exception on /explore [GET] [in /Users/stephentrento/flask_app/.venv/lib/python3.13/site-packages/flask/app.py:875]
Traceback (most recent call last):
  File "/Users/stephentrento/flask_app/.venv/lib/python3.13/site-packages/flask/app.py", line 1511, in wsgi_app
    response = self.full_dispatch_request()
  File "/Users/stephentrento/flask_app/.venv/lib/python3.13/site-packages/flask/app.py", line 919, in full_dispatch_request
    rv = self.handle_user_exception(e)
  File "/Users/stephentrento/flask_app/.venv/lib/python3.13/site-packages/flask/app.py", line 917, in full_dispatch_request
    rv = self.dispatch_request()
  File "/Users/stephentrento/flask_app/.venv/lib/python3.13/site-packages/flask/app.py", line 902, in dispatch_request
    return self.ensure_sync(self.view_functions[rule.endpoint])(**view_args)  # type: ignore[no-any-return]
           ~~~~~~~~~~~~~~~~~~~~~~~~~~~~~~~~~~~~~~~~~~~~~~~~~~~~^^^^^^^^^^^^^
  File "/Users/stephentrento/flask_app/.venv/lib/python3.13/site-packages/flask_login/utils.py", line 290, in decorated_view
    return current_app.ensure_sync(func)(*args, **kwargs)
           ~~~~~~~~~~~~~~~~~~~~~~~~~~~~~^^^^^^^^^^^^^^^^^
  File "/Users/stephentrento/flask_app/app/routes.py", line 277, in explore
    posts=posts.items, next_url=next_url,
          ^^^^^^^^^^^
AttributeError: 'list' object has no attribute 'items'
2025-02-22 22:53:36,444 INFO: Our Camden startup [in /Users/stephentrento/flask_app/app/__init__.py:51]
2025-02-22 22:54:45,722 INFO: Our Camden startup [in /Users/stephentrento/flask_app/app/__init__.py:51]
2025-02-22 22:54:58,618 INFO: Our Camden startup [in /Users/stephentrento/flask_app/app/__init__.py:51]
2025-02-22 22:55:27,219 INFO: Our Camden startup [in /Users/stephentrento/flask_app/app/__init__.py:51]
2025-02-22 22:56:13,575 INFO: Our Camden startup [in /Users/stephentrento/flask_app/app/__init__.py:51]
2025-02-22 22:57:26,034 INFO: Our Camden startup [in /Users/stephentrento/flask_app/app/__init__.py:51]
2025-02-22 23:09:04,200 INFO: Our Camden startup [in /Users/stephentrento/flask_app/app/__init__.py:51]
2025-02-22 23:29:23,154 INFO: Our Camden startup [in /Users/stephentrento/flask_app/app/__init__.py:51]
2025-02-22 23:33:55,166 INFO: Our Camden startup [in /Users/stephentrento/flask_app/app/__init__.py:51]
2025-02-22 23:39:41,354 INFO: Our Camden startup [in /Users/stephentrento/flask_app/app/__init__.py:51]
2025-02-22 23:41:10,134 INFO: Our Camden startup [in /Users/stephentrento/flask_app/app/__init__.py:51]
2025-02-22 23:41:45,768 INFO: Our Camden startup [in /Users/stephentrento/flask_app/app/__init__.py:51]
2025-02-22 23:48:49,451 INFO: Our Camden startup [in /Users/stephentrento/flask_app/app/__init__.py:51]
2025-02-22 23:56:21,570 INFO: Our Camden startup [in /Users/stephentrento/flask_app/app/__init__.py:51]
