2025-02-22 21:44:42,943 ERROR: Exception on /explore [GET] [in /Users/stephentrento/flask_app/.venv/lib/python3.13/site-packages/flask/app.py:875]
Traceback (most recent call last):
  File "/Users/stephentrento/flask_app/.venv/lib/python3.13/site-packages/flask/app.py", line 1511, in wsgi_app
    response = self.full_dispatch_request()
  File "/Users/stephentrento/flask_app/.venv/lib/python3.13/site-packages/flask/app.py", line 919, in full_dispatch_request
    rv = self.handle_user_exception(e)
  File "/Users/stephentrento/flask_app/.venv/lib/python3.13/site-packages/flask/app.py", line 917, in full_dispatch_request
    rv = self.dispatch_request()
  File "/Users/stephentrento/flask_app/.venv/lib/python3.13/site-packages/flask/app.py", line 902, in dispatch_request
    return self.ensure_sync(self.view_functions[rule.endpoint])(**view_args)  # type: ignore[no-any-return]
           ~~~~~~~~~~~~~~~~~~~~~~~~~~~~~~~~~~~~~~~~~~~~~~~~~~~~^^^^^^^^^^^^^
  File "/Users/stephentrento/flask_app/.venv/lib/python3.13/site-packages/flask_login/utils.py", line 290, in decorated_view
    return current_app.ensure_sync(func)(*args, **kwargs)
           ~~~~~~~~~~~~~~~~~~~~~~~~~~~~~^^^^^^^^^^^^^^^^^
  File "/Users/stephentrento/flask_app/app/routes.py", line 261, in explore
    search_results = Post.query.msearch(query, fields=['body', 'author'], limit=50).all() # filter the search for the query
                                        ^^^^^
NameError: name 'query' is not defined
2025-02-22 21:46:18,944 ERROR: Exception on /explore [GET] [in /Users/stephentrento/flask_app/.venv/lib/python3.13/site-packages/flask/app.py:875]
Traceback (most recent call last):
  File "/Users/stephentrento/flask_app/.venv/lib/python3.13/site-packages/flask/app.py", line 1511, in wsgi_app
    response = self.full_dispatch_request()
  File "/Users/stephentrento/flask_app/.venv/lib/python3.13/site-packages/flask/app.py", line 919, in full_dispatch_request
    rv = self.handle_user_exception(e)
  File "/Users/stephentrento/flask_app/.venv/lib/python3.13/site-packages/flask/app.py", line 917, in full_dispatch_request
    rv = self.dispatch_request()
  File "/Users/stephentrento/flask_app/.venv/lib/python3.13/site-packages/flask/app.py", line 902, in dispatch_request
    return self.ensure_sync(self.view_functions[rule.endpoint])(**view_args)  # type: ignore[no-any-return]
           ~~~~~~~~~~~~~~~~~~~~~~~~~~~~~~~~~~~~~~~~~~~~~~~~~~~~^^^^^^^^^^^^^
  File "/Users/stephentrento/flask_app/.venv/lib/python3.13/site-packages/flask_login/utils.py", line 290, in decorated_view
    return current_app.ensure_sync(func)(*args, **kwargs)
           ~~~~~~~~~~~~~~~~~~~~~~~~~~~~~^^^^^^^^^^^^^^^^^
  File "/Users/stephentrento/flask_app/app/routes.py", line 261, in explore
    search_results = Post.query.msearch(query, fields=['body', 'author'], limit=50).all() # filter the search for the query
                                        ^^^^^
NameError: name 'query' is not defined
2025-02-22 21:47:33,150 INFO: Our Camden startup [in /Users/stephentrento/flask_app/app/__init__.py:51]
2025-02-22 21:47:41,457 ERROR: Exception on /explore [GET] [in /Users/stephentrento/flask_app/.venv/lib/python3.13/site-packages/flask/app.py:875]
Traceback (most recent call last):
  File "/Users/stephentrento/flask_app/.venv/lib/python3.13/site-packages/flask/app.py", line 1511, in wsgi_app
    response = self.full_dispatch_request()
  File "/Users/stephentrento/flask_app/.venv/lib/python3.13/site-packages/flask/app.py", line 919, in full_dispatch_request
    rv = self.handle_user_exception(e)
  File "/Users/stephentrento/flask_app/.venv/lib/python3.13/site-packages/flask/app.py", line 917, in full_dispatch_request
    rv = self.dispatch_request()
  File "/Users/stephentrento/flask_app/.venv/lib/python3.13/site-packages/flask/app.py", line 902, in dispatch_request
    return self.ensure_sync(self.view_functions[rule.endpoint])(**view_args)  # type: ignore[no-any-return]
           ~~~~~~~~~~~~~~~~~~~~~~~~~~~~~~~~~~~~~~~~~~~~~~~~~~~~^^^^^^^^^^^^^
  File "/Users/stephentrento/flask_app/.venv/lib/python3.13/site-packages/flask_login/utils.py", line 290, in decorated_view
    return current_app.ensure_sync(func)(*args, **kwargs)
           ~~~~~~~~~~~~~~~~~~~~~~~~~~~~~^^^^^^^^^^^^^^^^^
  File "/Users/stephentrento/flask_app/app/routes.py", line 261, in explore
    search_results = Post.query.msearch(user_asks, fields=['body', 'author'], limit=50).all() # filter the search for the query
                     ~~~~~~~~~~~~~~~~~~^^^^^^^^^^^^^^^^^^^^^^^^^^^^^^^^^^^^^^^^^^^^^^^^
  File "/Users/stephentrento/flask_app/.venv/lib/python3.13/site-packages/flask_msearch/whoosh_backend.py", line 239, in msearch
    ix = _self.index(model)
  File "/Users/stephentrento/flask_app/.venv/lib/python3.13/site-packages/flask_msearch/whoosh_backend.py", line 151, in index
    self._indexs[name] = Index(
                         ~~~~~^
        model,
        ^^^^^^
    ...<3 lines>...
        self.index_name,
        ^^^^^^^^^^^^^^^^
    )
    ^
  File "/Users/stephentrento/flask_app/.venv/lib/python3.13/site-packages/flask_msearch/whoosh_backend.py", line 85, in __init__
    self._schema = Schema(self)
                   ~~~~~~^^^^^^
  File "/Users/stephentrento/flask_app/.venv/lib/python3.13/site-packages/flask_msearch/whoosh_backend.py", line 28, in __init__
    self.schema = _Schema(**self.fields)
                            ^^^^^^^^^^^
  File "/Users/stephentrento/flask_app/.venv/lib/python3.13/site-packages/flask_msearch/backends.py", line 80, in fields
    field_type = field_attr.property.columns[0].type
                 ^^^^^^^^^^^^^^^^^^^^^^^^^^^
  File "/Users/stephentrento/flask_app/.venv/lib/python3.13/site-packages/sqlalchemy/util/langhelpers.py", line 1332, in __getattr__
    return self._fallback_getattr(key)
           ~~~~~~~~~~~~~~~~~~~~~~^^^^^
  File "/Users/stephentrento/flask_app/.venv/lib/python3.13/site-packages/sqlalchemy/util/langhelpers.py", line 1301, in _fallback_getattr
    raise AttributeError(key)
AttributeError: columns
2025-02-22 21:47:49,072 ERROR: Exception on /explore [GET] [in /Users/stephentrento/flask_app/.venv/lib/python3.13/site-packages/flask/app.py:875]
Traceback (most recent call last):
  File "/Users/stephentrento/flask_app/.venv/lib/python3.13/site-packages/flask/app.py", line 1511, in wsgi_app
    response = self.full_dispatch_request()
  File "/Users/stephentrento/flask_app/.venv/lib/python3.13/site-packages/flask/app.py", line 919, in full_dispatch_request
    rv = self.handle_user_exception(e)
  File "/Users/stephentrento/flask_app/.venv/lib/python3.13/site-packages/flask/app.py", line 917, in full_dispatch_request
    rv = self.dispatch_request()
  File "/Users/stephentrento/flask_app/.venv/lib/python3.13/site-packages/flask/app.py", line 902, in dispatch_request
    return self.ensure_sync(self.view_functions[rule.endpoint])(**view_args)  # type: ignore[no-any-return]
           ~~~~~~~~~~~~~~~~~~~~~~~~~~~~~~~~~~~~~~~~~~~~~~~~~~~~^^^^^^^^^^^^^
  File "/Users/stephentrento/flask_app/.venv/lib/python3.13/site-packages/flask_login/utils.py", line 290, in decorated_view
    return current_app.ensure_sync(func)(*args, **kwargs)
           ~~~~~~~~~~~~~~~~~~~~~~~~~~~~~^^^^^^^^^^^^^^^^^
  File "/Users/stephentrento/flask_app/app/routes.py", line 261, in explore
    search_results = Post.query.msearch(user_asks, fields=['body', 'author'], limit=50).all() # filter the search for the query
                     ~~~~~~~~~~~~~~~~~~^^^^^^^^^^^^^^^^^^^^^^^^^^^^^^^^^^^^^^^^^^^^^^^^
  File "/Users/stephentrento/flask_app/.venv/lib/python3.13/site-packages/flask_msearch/whoosh_backend.py", line 239, in msearch
    ix = _self.index(model)
  File "/Users/stephentrento/flask_app/.venv/lib/python3.13/site-packages/flask_msearch/whoosh_backend.py", line 151, in index
    self._indexs[name] = Index(
                         ~~~~~^
        model,
        ^^^^^^
    ...<3 lines>...
        self.index_name,
        ^^^^^^^^^^^^^^^^
    )
    ^
  File "/Users/stephentrento/flask_app/.venv/lib/python3.13/site-packages/flask_msearch/whoosh_backend.py", line 85, in __init__
    self._schema = Schema(self)
                   ~~~~~~^^^^^^
  File "/Users/stephentrento/flask_app/.venv/lib/python3.13/site-packages/flask_msearch/whoosh_backend.py", line 28, in __init__
    self.schema = _Schema(**self.fields)
                            ^^^^^^^^^^^
  File "/Users/stephentrento/flask_app/.venv/lib/python3.13/site-packages/flask_msearch/backends.py", line 80, in fields
    field_type = field_attr.property.columns[0].type
                 ^^^^^^^^^^^^^^^^^^^^^^^^^^^
  File "/Users/stephentrento/flask_app/.venv/lib/python3.13/site-packages/sqlalchemy/util/langhelpers.py", line 1332, in __getattr__
    return self._fallback_getattr(key)
           ~~~~~~~~~~~~~~~~~~~~~~^^^^^
  File "/Users/stephentrento/flask_app/.venv/lib/python3.13/site-packages/sqlalchemy/util/langhelpers.py", line 1301, in _fallback_getattr
    raise AttributeError(key)
AttributeError: columns
2025-02-22 21:51:40,033 INFO: Our Camden startup [in /Users/stephentrento/flask_app/app/__init__.py:51]
