2025-02-19 23:44:33,570 ERROR: Exception on /register [POST] [in /Users/stephentrento/flask_app/.venv/lib/python3.13/site-packages/flask/app.py:875]
Traceback (most recent call last):
  File "/Users/stephentrento/flask_app/.venv/lib/python3.13/site-packages/flask/app.py", line 1511, in wsgi_app
    response = self.full_dispatch_request()
  File "/Users/stephentrento/flask_app/.venv/lib/python3.13/site-packages/flask/app.py", line 919, in full_dispatch_request
    rv = self.handle_user_exception(e)
  File "/Users/stephentrento/flask_app/.venv/lib/python3.13/site-packages/flask/app.py", line 917, in full_dispatch_request
    rv = self.dispatch_request()
  File "/Users/stephentrento/flask_app/.venv/lib/python3.13/site-packages/flask/app.py", line 902, in dispatch_request
    return self.ensure_sync(self.view_functions[rule.endpoint])(**view_args)  # type: ignore[no-any-return]
           ~~~~~~~~~~~~~~~~~~~~~~~~~~~~~~~~~~~~~~~~~~~~~~~~~~~~^^^^^^^^^^^^^
  File "/Users/stephentrento/flask_app/app/routes.py", line 291, in register
    if form.validate_on_submit(): # if all required inputs given
       ~~~~~~~~~~~~~~~~~~~~~~~^^
  File "/Users/stephentrento/flask_app/.venv/lib/python3.13/site-packages/flask_wtf/form.py", line 86, in validate_on_submit
    return self.is_submitted() and self.validate(extra_validators=extra_validators)
                                   ~~~~~~~~~~~~~^^^^^^^^^^^^^^^^^^^^^^^^^^^^^^^^^^^
  File "/Users/stephentrento/flask_app/.venv/lib/python3.13/site-packages/wtforms/form.py", line 330, in validate
    return super().validate(extra)
           ~~~~~~~~~~~~~~~~^^^^^^^
  File "/Users/stephentrento/flask_app/.venv/lib/python3.13/site-packages/wtforms/form.py", line 147, in validate
    if not field.validate(self, extra):
           ~~~~~~~~~~~~~~^^^^^^^^^^^^^
  File "/Users/stephentrento/flask_app/.venv/lib/python3.13/site-packages/wtforms/fields/core.py", line 234, in validate
    stop_validation = self._run_validation_chain(form, chain)
  File "/Users/stephentrento/flask_app/.venv/lib/python3.13/site-packages/wtforms/fields/core.py", line 254, in _run_validation_chain
    validator(form, self)
    ~~~~~~~~~^^^^^^^^^^^^
  File "/Users/stephentrento/flask_app/app/forms.py", line 35, in is_strong_password
    flash('Password must be atleast 8 characters')
    ^^^^^
NameError: name 'flash' is not defined. Did you mean: 'hash'?
2025-02-19 23:46:37,216 INFO: Our Camden startup [in /Users/stephentrento/flask_app/app/__init__.py:51]
2025-02-19 23:47:19,962 ERROR: Exception on /register [POST] [in /Users/stephentrento/flask_app/.venv/lib/python3.13/site-packages/flask/app.py:875]
Traceback (most recent call last):
  File "/Users/stephentrento/flask_app/.venv/lib/python3.13/site-packages/flask/app.py", line 1511, in wsgi_app
    response = self.full_dispatch_request()
  File "/Users/stephentrento/flask_app/.venv/lib/python3.13/site-packages/flask/app.py", line 919, in full_dispatch_request
    rv = self.handle_user_exception(e)
  File "/Users/stephentrento/flask_app/.venv/lib/python3.13/site-packages/flask/app.py", line 917, in full_dispatch_request
    rv = self.dispatch_request()
  File "/Users/stephentrento/flask_app/.venv/lib/python3.13/site-packages/flask/app.py", line 902, in dispatch_request
    return self.ensure_sync(self.view_functions[rule.endpoint])(**view_args)  # type: ignore[no-any-return]
           ~~~~~~~~~~~~~~~~~~~~~~~~~~~~~~~~~~~~~~~~~~~~~~~~~~~~^^^^^^^^^^^^^
  File "/Users/stephentrento/flask_app/app/routes.py", line 291, in register
    if form.validate_on_submit(): # if all required inputs given
       ~~~~~~~~~~~~~~~~~~~~~~~^^
  File "/Users/stephentrento/flask_app/.venv/lib/python3.13/site-packages/flask_wtf/form.py", line 86, in validate_on_submit
    return self.is_submitted() and self.validate(extra_validators=extra_validators)
                                   ~~~~~~~~~~~~~^^^^^^^^^^^^^^^^^^^^^^^^^^^^^^^^^^^
  File "/Users/stephentrento/flask_app/.venv/lib/python3.13/site-packages/wtforms/form.py", line 330, in validate
    return super().validate(extra)
           ~~~~~~~~~~~~~~~~^^^^^^^
  File "/Users/stephentrento/flask_app/.venv/lib/python3.13/site-packages/wtforms/form.py", line 147, in validate
    if not field.validate(self, extra):
           ~~~~~~~~~~~~~~^^^^^^^^^^^^^
  File "/Users/stephentrento/flask_app/.venv/lib/python3.13/site-packages/wtforms/fields/core.py", line 234, in validate
    stop_validation = self._run_validation_chain(form, chain)
  File "/Users/stephentrento/flask_app/.venv/lib/python3.13/site-packages/wtforms/fields/core.py", line 254, in _run_validation_chain
    validator(form, self)
    ~~~~~~~~~^^^^^^^^^^^^
  File "/Users/stephentrento/flask_app/app/forms.py", line 36, in is_strong_password
    elif not re.search("[a-z]", password.data):
             ^^
NameError: name 're' is not defined. Did you forget to import 're'?
2025-02-19 23:47:34,834 INFO: Our Camden startup [in /Users/stephentrento/flask_app/app/__init__.py:51]
2025-02-20 00:00:18,943 INFO: Our Camden startup [in /Users/stephentrento/flask_app/app/__init__.py:51]
2025-02-20 00:01:07,530 INFO: Our Camden startup [in /Users/stephentrento/flask_app/app/__init__.py:51]
2025-02-20 00:04:13,157 INFO: Our Camden startup [in /Users/stephentrento/flask_app/app/__init__.py:51]
2025-02-20 00:11:10,814 INFO: Our Camden startup [in /Users/stephentrento/flask_app/app/__init__.py:51]
2025-02-20 00:14:10,365 INFO: Our Camden startup [in /Users/stephentrento/flask_app/app/__init__.py:51]
2025-02-20 00:14:28,438 INFO: Our Camden startup [in /Users/stephentrento/flask_app/app/__init__.py:51]
2025-02-20 00:17:48,559 INFO: Our Camden startup [in /Users/stephentrento/flask_app/app/__init__.py:51]
2025-02-20 00:19:29,708 INFO: Our Camden startup [in /Users/stephentrento/flask_app/app/__init__.py:51]
2025-02-20 08:55:41,841 INFO: Our Camden startup [in /Users/stephentrento/flask_app/app/__init__.py:51]
2025-02-20 10:04:07,074 ERROR: Exception on /map [GET] [in /Users/stephentrento/flask_app/.venv/lib/python3.13/site-packages/flask/app.py:875]
Traceback (most recent call last):
  File "/Users/stephentrento/flask_app/.venv/lib/python3.13/site-packages/flask/app.py", line 1511, in wsgi_app
    response = self.full_dispatch_request()
  File "/Users/stephentrento/flask_app/.venv/lib/python3.13/site-packages/flask/app.py", line 919, in full_dispatch_request
    rv = self.handle_user_exception(e)
  File "/Users/stephentrento/flask_app/.venv/lib/python3.13/site-packages/flask/app.py", line 917, in full_dispatch_request
    rv = self.dispatch_request()
  File "/Users/stephentrento/flask_app/.venv/lib/python3.13/site-packages/flask/app.py", line 902, in dispatch_request
    return self.ensure_sync(self.view_functions[rule.endpoint])(**view_args)  # type: ignore[no-any-return]
           ~~~~~~~~~~~~~~~~~~~~~~~~~~~~~~~~~~~~~~~~~~~~~~~~~~~~^^^^^^^^^^^^^
  File "/Users/stephentrento/flask_app/app/routes.py", line 96, in map
    return render_template('map.html', form=form, user_access_level=current_user.access_level, user_id=current_user.id)
                                                                    ^^^^^^^^^^^^^^^^^^^^^^^^^
AttributeError: 'AnonymousUserMixin' object has no attribute 'access_level'
2025-02-20 10:31:28,709 INFO: Our Camden startup [in /Users/stephentrento/flask_app/app/__init__.py:51]
2025-02-20 10:31:45,468 ERROR: Exception on /map [GET] [in /Users/stephentrento/flask_app/.venv/lib/python3.13/site-packages/flask/app.py:875]
Traceback (most recent call last):
  File "/Users/stephentrento/flask_app/.venv/lib/python3.13/site-packages/flask/app.py", line 1511, in wsgi_app
    response = self.full_dispatch_request()
  File "/Users/stephentrento/flask_app/.venv/lib/python3.13/site-packages/flask/app.py", line 919, in full_dispatch_request
    rv = self.handle_user_exception(e)
  File "/Users/stephentrento/flask_app/.venv/lib/python3.13/site-packages/flask/app.py", line 917, in full_dispatch_request
    rv = self.dispatch_request()
  File "/Users/stephentrento/flask_app/.venv/lib/python3.13/site-packages/flask/app.py", line 902, in dispatch_request
    return self.ensure_sync(self.view_functions[rule.endpoint])(**view_args)  # type: ignore[no-any-return]
           ~~~~~~~~~~~~~~~~~~~~~~~~~~~~~~~~~~~~~~~~~~~~~~~~~~~~^^^^^^^^^^^^^
  File "/Users/stephentrento/flask_app/app/routes.py", line 96, in map
    return render_template('map.html', form=form, user_access_level=current_user.access_level, user_id=current_user.id)
                                                                    ^^^^^^^^^^^^^^^^^^^^^^^^^
AttributeError: 'AnonymousUserMixin' object has no attribute 'access_level'
2025-02-20 11:04:18,310 INFO: Our Camden startup [in /Users/stephentrento/flask_app/app/__init__.py:51]
2025-02-20 11:04:53,318 ERROR: Exception on /update_user/8 [POST] [in /Users/stephentrento/flask_app/.venv/lib/python3.13/site-packages/flask/app.py:875]
Traceback (most recent call last):
  File "/Users/stephentrento/flask_app/.venv/lib/python3.13/site-packages/flask/app.py", line 1511, in wsgi_app
    response = self.full_dispatch_request()
  File "/Users/stephentrento/flask_app/.venv/lib/python3.13/site-packages/flask/app.py", line 919, in full_dispatch_request
    rv = self.handle_user_exception(e)
  File "/Users/stephentrento/flask_app/.venv/lib/python3.13/site-packages/flask/app.py", line 917, in full_dispatch_request
    rv = self.dispatch_request()
  File "/Users/stephentrento/flask_app/.venv/lib/python3.13/site-packages/flask/app.py", line 902, in dispatch_request
    return self.ensure_sync(self.view_functions[rule.endpoint])(**view_args)  # type: ignore[no-any-return]
           ~~~~~~~~~~~~~~~~~~~~~~~~~~~~~~~~~~~~~~~~~~~~~~~~~~~~^^^^^^^^^^^^^
  File "/Users/stephentrento/flask_app/app/routes.py", line 185, in update_user
    setattr(user, data['field'], data['value'])  # Update dynamically
                  ^^^^
NameError: name 'data' is not defined
